Workbook

Sheet Dashboard-Site Prep.
A22: No. | B22: Tasks | C22: % Complete | D22: Status
A23: HQ | B23: New AP Cabling > | C23: ='HQ-WL'!N118/'HQ-WL'!M118 -> 1 | D23: ="ทั้งหมด " &'HQ-WL'!M118 & " จุด - Completed" -> ทั้งหมด 17 จุด - Completed
B24: Electrical System > | C24: ='HQ-PW'!O33/'HQ-PW'!B33 -> 1 | D24: ="ทั้งหมด " &'HQ-PW'!B33 & " จุด - Completed" -> ทั้งหมด 31 จุด - Completed
A25: SVB | B25: New AP Cabling > | C25: ='SVB-WL'!G80/'SVB-WL'!F80 -> 0.97435897 | D25: ="ทั้งหมด "&'SVB-WL'!F80 & " จุด" -> ทั้งหมด 156 จุด
B26: Electrical System > | C26: ='SVB-PW'!Y98/'SVB-PW'!B98 -> 1 | D26: ="ทั้งหมด " &'SVB-PW'!B98 & " จุด - Completed" -> ทั้งหมด 96 จุด - Completed
A27: HKT | B27: New AP Cabling > | C27: ='HKT-WL'!G46/'HKT-WL'!F46 -> 1 | D27: ="ทั้งหมด " &'HKT-WL'!F46 & " จุด - Completed" -> ทั้งหมด 15 จุด - Completed
B28: Electrical System > | C28: ='HKT-PW'!O58/'HKT-PW'!B58 -> 1 | D28: ="ทั้งหมด " &'HKT-PW'!B58 & " จุด - Completed" -> ทั้งหมด 56 จุด - Completed
A29: CNX | B29: New AP Cabling > | C29: 1 | D29: ="ทั้งหมด " &'CNX-WL'!F44 & " จุด - Completed" -> ทั้งหมด 0 จุด - Completed
B30: Electrical System > | C30: ='CNX-PW'!O12/'CNX-PW'!B12 -> 1 | D30: ="ทั้งหมด " &'CNX-PW'!B12 & " จุด - Completed" -> ทั้งหมด 10 จุด - Completed
A31: HDY | B31: New AP Cabling > | C31: ='HDY-WL'!G44/'HDY-WL'!F44 -> 1 | D31: ="ทั้งหมด " &'HDY-WL'!F44 & " จุด - Completed" -> ทั้งหมด 2 จุด - Completed
B32: Electrical System > | C32: ='HDY-PW'!O25/'HDY-PW'!B25 -> 1 | D32: ="ทั้งหมด " &'HDY-PW'!B25 & " จุด - Completed" -> ทั้งหมด 23 จุด - Completed
A33: CEI | B33: New AP Cabling > | C33: 1 | D33: ="ทั้งหมด " &'CEI-WL'!F22 & " จุด - Completed" -> ทั้งหมด 0 จุด - Completed
B34: Electrical System > | C34: ='CEI-PW'!O18/'CEI-PW'!B18 -> 1 | D34: ="ทั้งหมด " &'CEI-PW'!B18 & " จุด - Completed" -> ทั้งหมด 16 จุด - Completed

Sheet Dashboard-LAN
A22: No. | B22: Tasks | C22: % Complete | D22: Status
A23: HQ | B23: Configuration > | C23: =HQ!N90 -> 0.97409326
B24: Installation > | C24: =HQ!O90 -> 0.97409326
B25: Migration > | C25: =HQ!P90 -> 0.94818653
A26: SVB | B26: Configuration > | C26: =SVB!M741 -> 0.28894472
B27: Installation > | C27: =SVB!N741 -> 0.28894472
B28: Migration > | C28: =SVB!O741 -> 0.28894472
A29: HKT | B29: Configuration > | C29: ='HKT (OLD)'!G96 -> 0.02970297
B30: Installation > | C30: ='HKT (OLD)'!H96 -> 0.02970297
B31: Migration > | C31: ='HKT (OLD)'!I96 -> 0
A32: CNX | B32: Configuration > | C32: =CNX!N49 -> 1
B33: Installation > | C33: =CNX!O49 -> 1
B34: Migration > | C34: =CNX!P49 -> 1
A35: HDY | B35: Configuration > | C35: ='HDY (OLD)'!F46 -> 0.3372093
B36: Installation > | C36: ='HDY (OLD)'!G46 -> 0.3372093
B37: Migration > | C37: ='HDY (OLD)'!H46 -> 0
A38: CEI | B38: Configuration > | C38: ='CEI (Old)'!F35 -> 0.026315789
B39: Installation > | C39: ='CEI (Old)'!G35 -> 0
B40: Migration > | C40: ='CEI (Old)'!H35 -> 0

Sheet Dashboard-WL
A22: No. | B22: Tasks | C22: % Complete | D22: Status
A23: HQ | B23: Configuration > | C23: ='HQ-WL'!O119 -> 1
B24: Installation > | C24: ='HQ-WL'!P119 -> 1 | D24: ="ทั้งหมด " &'HQ-WL'!K118 & " ชุด" -> ทั้งหมด 167 ชุด
B25: Migration > | C25: ='HQ-WL'!Q119 -> 1
A26: SVB | B26: Configuration > | C26: ='SVB-WL'!I81 -> 0.13033708
B27: Installation > | C27: ='SVB-WL'!J81 -> 0.39775281 | D27: ="ทั้งหมด " &'SVB-WL'!D80 & " ชุด" -> ทั้งหมด 445 ชุด
B28: Migration > | C28: ='SVB-WL'!K81 -> 0.13033708
A29: HKT | B29: Configuration > | C29: ='HKT-WL'!H47 -> 0.86
B30: Installation > | C30: ='HKT-WL'!I47 -> 0.86 | D30: ="ทั้งหมด " &'HKT-WL'!D46 & " ชุด" -> ทั้งหมด 50 ชุด
B31: Migration > | C31: ='HKT-WL'!J47 -> 0.86
A32: CNX | B32: Configuration > | C32: ='CNX-WL'!H45 -> 1
B33: Installation > | C33: ='CNX-WL'!I45 -> 1 | D33: ="ทั้งหมด " &'CNX-WL'!D44 & " ชุด" -> ทั้งหมด 50 ชุด
B34: Migration > | C34: ='CNX-WL'!J45 -> 1
A35: HDY | B35: Configuration > | C35: ='HDY-WL'!H45 -> 0
B36: Installation > | C36: ='HDY-WL'!I45 -> 0 | D36: ="ทั้งหมด " &'HDY-WL'!D44 & " ชุด" -> ทั้งหมด 45 ชุด
B37: Migration > | C37: ='HDY-WL'!J45 -> 0
A38: CEI | B38: Configuration > | C38: ='CEI-WL'!H23 -> 0
B39: Installation > | C39: ='CEI-WL'!I23 -> 0 | D39: ="ทั้งหมด " &'CEI-WL'!D22 & " ชุด" -> ทั้งหมด 30 ชุด
B40: Migration > | C40: ='CEI-WL'!J23 -> 0

Sheet HQ
A1: สถานที่ | B1: ห้อง | C1: ชั้น | D1: อุปกรณ์ | E1: ยี่ห้อ รุ่น | F1: จำนวน TOR | G1: จำนวน ใหม่ | H1: Migration Plan | J1: Install Date | K1: Complete Date | L1: Status | M1: หมายเหตุ | N1: Configuration | O1: Installation | P1: Migration | Q1: Total | R1: Remark | S1: Category | T1: วันที่เริ่ม (Helper) | U1: วันที่ติดตั้ง (Helper) | V1: วันที่สิ้นสุด (Helper)
H2: เริ่ม | I2: ถึง
A3: อาคารสายงานวิศวกรรมศาสตร์และเทคโนโลยีสารสนเทศ (สงวท.) | B3: ห้องไฟฟ้า | C3: 1 | D3: อุปกรณ์กระจายสัญญาณเครือข่ายแบบที่ 2 (Access Switch Type 2) | E3: Cisco /C9300L-24T-4X | F3: 4 | G3: 0 | H3: - | I3: - | K3: - | L3: - | M3: ย้ายไปห้องอื่น | N3: 0 | O3: 0 | P3: 0 | Q3: =IF($G3=0,1,(N3+O3+P3)/($G3*3)) -> 1 | S3: =IF(ISNUMBER(SEARCH("Access Point",D3)),"AP",IF(OR(ISNUMBER(SEARCH("Switch",D3)),ISNUMBER(SEARCH("Control Type",D3))),"Switch","Infra")) -> Switch
A4: อาคารสายงานวิศวกรรมศาสตร์และเทคโนโลยีสารสนเทศ (สงวท.) | B4: ห้องไฟฟ้า | D4: อุปกรณ์กระจายสัญญาณเครือข่ายแบบที่ 4 (Access Switch Type 4) | E4: Cisco /C9300L-24UXG-4X | F4: 1 | G4: 0 | N4: 0 | O4: 0 | P4: 0 | Q4: =IF($G4=0,1,(N4+O4+P4)/($G4*3)) -> 1 | S4: =IF(ISNUMBER(SEARCH("Access Point",D4)),"AP",IF(OR(ISNUMBER(SEARCH("Switch",D4)),ISNUMBER(SEARCH("Control Type",D4))),"Switch","Infra")) -> Switch
A5: อาคารสายงานวิศวกรรมศาสตร์และเทคโนโลยีสารสนเทศ (สงวท.) | B5: ชั้น 2 Data Center | C5: 2 | D5: ระบบบริหารจัดการ อุปกรณ์รักษาความปลอดภัยระบบเครือข่ายจากส่วนกลาง (Centralized Management) | E5: Paloalto/M300 | F5: 1 | G5: 1 | H5: 46056 | I5: 46094 | J5: 46056 | L5: In Progress | N5: 1 | O5: 1 | P5: 0 | Q5: =IF($G5=0,1,(N5+O5+P5)/($G5*3)) -> 0.66666667 | S5: =IF(ISNUMBER(SEARCH("Access Point",D5)),"AP",IF(OR(ISNUMBER(SEARCH("Switch",D5)),ISNUMBER(SEARCH("Control Type",D5))),"Switch","Infra")) -> Infra | T5: =$H$5 -> 46056 | U5: =$J$5 -> 46056 | V5: =$I$5 -> 46094
A6: อาคารสายงานวิศวกรรมศาสตร์และเทคโนโลยีสารสนเทศ (สงวท.) | B6: ชั้น 2 Data Center | D6: อุปกรณ์เชื่อมต่อระบบกับเครือข่ายภายนอกแบบที่ 1 (Extranet Switch Type 1) | E6: Cisco /C9500-48Y4C | F6: 2 | G6: 2 | L6: In Progress | N6: 2 | O6: 2 | P6: 2 | Q6: =IF($G6=0,1,(N6+O6+P6)/($G6*3)) -> 1 | S6: =IF(ISNUMBER(SEARCH("Access Point",D6)),"AP",IF(OR(ISNUMBER(SEARCH("Switch",D6)),ISNUMBER(SEARCH("Control Type",D6))),"Switch","Infra")) -> Switch | T6: =$H$5 -> 46056 | U6: =$J$5 -> 46056 | V6: =$I$5 -> 46094
A7: อาคารสายงานวิศวกรรมศาสตร์และเทคโนโลยีสารสนเทศ (สงวท.) | B7: ชั้น 2 Data Center | D7: อุปกรณ์กระจายสัญญาณเครือข่ายแบบที่ 2 (Access Switch Type 2) | E7: Cisco /C9300L-24T-4X | F7: 7 | G7: 6 | L7: In Progress | N7: 3 | O7: 3 | P7: 3 | Q7: =IF($G7=0,1,(N7+O7+P7)/($G7*3)) -> 0.5 | S7: =IF(ISNUMBER(SEARCH("Access Point",D7)),"AP",IF(OR(ISNUMBER(SEARCH("Switch",D7)),ISNUMBER(SEARCH("Control Type",D7))),"Switch","Infra")) -> Switch | T7: =$H$5 -> 46056 | U7: =$J$5 -> 46056 | V7: =$I$5 -> 46094
A8: อาคารสายงานวิศวกรรมศาสตร์และเทคโนโลยีสารสนเทศ (สงวท.) | B8: ชั้น 2 Data Center | D8: อุปกรณ์กระจายสัญญาณเครือข่ายแบบที่ 4 (Access Switch Type 4) | E8: Cisco /C9300L-24UXG-4X | F8: 1 | G8: 1 | L8: In Progress | N8: 0 | O8: 0 | P8: 0 | Q8: =IF($G8=0,1,(N8+O8+P8)/($G8*3)) -> 0 | S8: =IF(ISNUMBER(SEARCH("Access Point",D8)),"AP",IF(OR(ISNUMBER(SEARCH("Switch",D8)),ISNUMBER(SEARCH("Control Type",D8))),"Switch","Infra")) -> Switch | T8: =$H$5 -> 46056 | U8: =$J$5 -> 46056 | V8: =$I$5 -> 46094
A9: อาคารสายงานวิศวกรรมศาสตร์และเทคโนโลยีสารสนเทศ (สงวท.) | B9: ชั้น 2 Data Center | D9: อุปกรณ์ควบคุมการเข้าถึงระบบเครือข่ายแบบที่ 1 (Access Control Type 1) | E9: Cisco /SNS-3755 | F9: 4 | G9: 4 | L9: In Progress | N9: 4 | O9: 4 | P9: 4 | Q9: =IF($G9=0,1,(N9+O9+P9)/($G9*3)) -> 1 | S9: =IF(ISNUMBER(SEARCH("Access Point",D9)),"AP",IF(OR(ISNUMBER(SEARCH("Switch",D9)),ISNUMBER(SEARCH("Control Type",D9))),"Switch","Infra")) -> Switch | T9: =$H$5 -> 46056 | U9: =$J$5 -> 46056 | V9: =$I$5 -> 46094
A10: อาคารสายงานวิศวกรรมศาสตร์และเทคโนโลยีสารสนเทศ (สงวท.) | B10: ชั้น 2 Data Center | D10: อุปกรณ์ควบคุมการกระจายสัญญาณเครือข่ายไร้สาย (Wireless Controller) | E10: Cisco /C9800-L-F | F10: 2 | G10: 2 | L10: In Progress | N10: 2 | O10: 2 | P10: 2 | Q10: =IF($G10=0,1,(N10+O10+P10)/($G10*3)) -> 1 | S10: =IF(ISNUMBER(SEARCH("Access Point",D10)),"AP",IF(OR(ISNUMBER(SEARCH("Switch",D10)),ISNUMBER(SEARCH("Control Type",D10))),"Switch","Infra")) -> Infra | T10: =$H$5 -> 46056 | U10: =$J$5 -> 46056 | V10: =$I$5 -> 46094
A11: อาคารสายงานวิศวกรรมศาสตร์และเทคโนโลยีสารสนเทศ (สงวท.) | B11: ชั้น 2 Data Center | D11: อุปกรณ์ควบคุมระบบครือข่ายด้วยซอฟต์แวร์ (SDN Controller) | E11: Cisco /DN3-HW-APL-XL | F11: 3 | G11: 3 | L11: In Progress | N11: 3 | O11: 3 | P11: 3 | Q11: =IF($G11=0,1,(N11+O11+P11)/($G11*3)) -> 1 | S11: =IF(ISNUMBER(SEARCH("Access Point",D11)),"AP",IF(OR(ISNUMBER(SEARCH("Switch",D11)),ISNUMBER(SEARCH("Control Type",D11))),"Switch","Infra")) -> Infra | T11: =$H$5 -> 46056 | U11: =$J$5 -> 46056 | V11: =$I$5 -> 46094
A12: อาคารสายงานวิศวกรรมศาสตร์และเทคโนโลยีสารสนเทศ (สงวท.) | B12: ชั้น 2 Data Center | D12: อุปกรณ์รักษาความปลอดภัยระบบเครือข่าย Next Generation Firewall แบบที่ 1 | E12: Paloalto/PA-3420 | F12: 2 | G12: 2 | L12: In Progress | N12: 2 | O12: 2 | P12: 0 | Q12: =IF($G12=0,1,(N12+O12+P12)/($G12*3)) -> 0.66666667 | S12: =IF(ISNUMBER(SEARCH("Access Point",D12)),"AP",IF(OR(ISNUMBER(SEARCH("Switch",D12)),ISNUMBER(SEARCH("Control Type",D12))),"Switch","Infra")) -> Infra | T12: =$H$5 -> 46056 | U12: =$J$5 -> 46056 | V12: =$I$5 -> 46094
A13: อาคารสายงานวิศวกรรมศาสตร์และเทคโนโลยีสารสนเทศ (สงวท.) | B13: ชั้น 2 Data Center | D13: อุปกรณ์รักษาความปลอดภัยระบบเครือข่าย Next Generation Firewall แบบที่ 2 | E13: Paloalto/PA-3410 | F13: 2 | G13: 2 | L13: In Progress | N13: 2 | O13: 2 | P13: 2 | Q13: =IF($G13=0,1,(N13+O13+P13)/($G13*3)) -> 1 | S13: =IF(ISNUMBER(SEARCH("Access Point",D13)),"AP",IF(OR(ISNUMBER(SEARCH("Switch",D13)),ISNUMBER(SEARCH("Control Type",D13))),"Switch","Infra")) -> Infra | T13: =$H$5 -> 46056 | U13: =$J$5 -> 46056 | V13: =$I$5 -> 46094
A14: อาคารสายงานวิศวกรรมศาสตร์และเทคโนโลยีสารสนเทศ (สงวท.) | B14: ชั้น 2 Data Center | D14: อุปกรณ์ Web Application Firewall | E14: Imperva/X6530 | F14: 1 | G14: 1 | L14: In Progress | N14: 1 | O14: 1 | P14: 1 | Q14: =IF($G14=0,1,(N14+O14+P14)/($G14*3)) -> 1 | S14: =IF(ISNUMBER(SEARCH("Access Point",D14)),"AP",IF(OR(ISNUMBER(SEARCH("Switch",D14)),ISNUMBER(SEARCH("Control Type",D14))),"Switch","Infra")) -> Infra | T14: =$H$5 -> 46056 | U14: =$J$5 -> 46056 | V14: =$I$5 -> 46094
A15: อาคารสายงานวิศวกรรมศาสตร์และเทคโนโลยีสารสนเทศ (สงวท.) | B15: ชั้น 2 Data Center | D15: อุปกรณ์กระจายสัญญาณเครือข่ายหลักแบบที่ 2 (Core Switch Type 2) | E15: Cisco /C9407R | F15: 2 | G15: 2 | L15: In Progress | N15: 2 | O15: 2 | P15: 2 | Q15: =IF($G15=0,1,(N15+O15+P15)/($G15*3)) -> 1 | S15: =IF(ISNUMBER(SEARCH("Access Point",D15)),"AP",IF(OR(ISNUMBER(SEARCH("Switch",D15)),ISNUMBER(SEARCH("Control Type",D15))),"Switch","Infra")) -> Switch | T15: =$H$5 -> 46056 | U15: =$J$5 -> 46056 | V15: =$I$5 -> 46094
A16: อาคารสายงานวิศวกรรมศาสตร์และเทคโนโลยีสารสนเทศ (สงวท.) | B16: ชั้น 2 Data Center | D16: อุปกรณ์เชื่อมต่อระบบกับเครือข่ายภายในแบบที่ 1 (Fusion Switch Type 1) | E16: Cisco /C9606R | F16: 2 | G16: 2 | L16: In Progress | N16: 2 | O16: 2 | P16: 2 | Q16: =IF($G16=0,1,(N16+O16+P16)/($G16*3)) -> 1 | S16: =IF(ISNUMBER(SEARCH("Access Point",D16)),"AP",IF(OR(ISNUMBER(SEARCH("Switch",D16)),ISNUMBER(SEARCH("Control Type",D16))),"Switch","Infra")) -> Switch | T16: =$H$5 -> 46056 | U16: =$J$5 -> 46056 | V16: =$I$5 -> 46094
A17: อาคารสายงานวิศวกรรมศาสตร์และเทคโนโลยีสารสนเทศ (สงวท.) | B17: ห้องไฟฟ้า 102 | C17: 1 | D17: อุปกรณ์กระจายสัญญาณเครือข่ายแบบที่ 2 (Access Switch Type 2) | E17: Cisco /C9300L-24T-4X | F17: 6 | G17: 5 | H17: 46064 | I17: 46065 | J17: 46064 | K17: 46064 | L17: Complete | M17: ย้าย TPYE 2 ไปชั้น 4 สงวท 1 ตัว | N17: 5 | O17: 5 | P17: 5 | Q17: =IF($G17=0,1,(N17+O17+P17)/($G17*3)) -> 1 | S17: =IF(ISNUMBER(SEARCH("Access Point",D17)),"AP",IF(OR(ISNUMBER(SEARCH("Switch",D17)),ISNUMBER(SEARCH("Control Type",D17))),"Switch","Infra")) -> Switch | T17: =$H$17 -> 46064 | U17: =$J$17 -> 46064 | V17: =$I$17 -> 46065
A18: อาคารสายงานวิศวกรรมศาสตร์และเทคโนโลยีสารสนเทศ (สงวท.) | B18: ห้องไฟฟ้า 102 | D18: อุปกรณ์กระจายสัญญาณเครือข่ายแบบที่ 4 (Access Switch Type 4) | E18: Cisco /C9300L-24UXG-4X | F18: 5 | G18: 5 | N18: 5 | O18: 5 | P18: 5 | Q18: =IF($G18=0,1,(N18+O18+P18)/($G18*3)) -> 1 | S18: =IF(ISNUMBER(SEARCH("Access Point",D18)),"AP",IF(OR(ISNUMBER(SEARCH("Switch",D18)),ISNUMBER(SEARCH("Control Type",D18))),"Switch","Infra")) -> Switch | T18: =$H$17 -> 46064 | U18: =$J$17 -> 46064 | V18: =$I$17 -> 46065
A19: อาคารสายงานวิศวกรรมศาสตร์และเทคโนโลยีสารสนเทศ (สงวท.) | B19: ห้องเก็บของ | C19: 2 | D19: อุปกรณ์กระจายสัญญาณเครือข่ายแบบที่ 2 (Access Switch Type 2) | E19: Cisco /C9300L-24T-4X | F19: 3 | G19: 3 | H19: 46056 | I19: 46057 | J19: 46056 | K19: 46060 | L19: Complete | M19: ชื่อห้องเดิมคือ ชั้น 2 ห้องฝ่ายระบบคอมพิวเตอร์และเครือข่าย *** เป็น Pilot Site | N19: 3 | O19: 3 | P19: 3 | Q19: =IF($G19=0,1,(N19+O19+P19)/($G19*3)) -> 1 | S19: =IF(ISNUMBER(SEARCH("Access Point",D19)),"AP",IF(OR(ISNUMBER(SEARCH("Switch",D19)),ISNUMBER(SEARCH("Control Type",D19))),"Switch","Infra")) -> Switch | T19: =$H$19 -> 46056 | U19: =$J$19 -> 46056 | V19: =$I$19 -> 46057
A20: อาคารสายงานวิศวกรรมศาสตร์และเทคโนโลยีสารสนเทศ (สงวท.) | B20: ห้องเก็บของ | D20: อุปกรณ์กระจายสัญญาณเครือข่ายแบบที่ 4 (Access Switch Type 4) | E20: Cisco /C9300L-24UXG-4X | F20: 3 | G20: 3 | N20: 3 | O20: 3 | P20: 3 | Q20: =IF($G20=0,1,(N20+O20+P20)/($G20*3)) -> 1 | S20: =IF(ISNUMBER(SEARCH("Access Point",D20)),"AP",IF(OR(ISNUMBER(SEARCH("Switch",D20)),ISNUMBER(SEARCH("Control Type",D20))),"Switch","Infra")) -> Switch | T20: =$H$19 -> 46056 | U20: =$J$19 -> 46056 | V20: =$I$19 -> 46057
A21: อาคารสายงานวิศวกรรมศาสตร์และเทคโนโลยีสารสนเทศ (สงวท.) | B21: ห้องไฟฟ้า 301 | C21: 3 | D21: อุปกรณ์กระจายสัญญาณเครือข่ายแบบที่ 2 (Access Switch Type 2) | E21: Cisco /C9300L-24T-4X | F21: 1 | G21: 1 | H21: 46071 | I21: 46073 | J21: 46071 | K21: 46071 | L21: Complete | N21: 1 | O21: 1 | P21: 1 | Q21: =IF($G21=0,1,(N21+O21+P21)/($G21*3)) -> 1 | S21: =IF(ISNUMBER(SEARCH("Access Point",D21)),"AP",IF(OR(ISNUMBER(SEARCH("Switch",D21)),ISNUMBER(SEARCH("Control Type",D21))),"Switch","Infra")) -> Switch | T21: =$H$21 -> 46071 | U21: =$J$21 -> 46071 | V21: =$I$21 -> 46073
A22: อาคารสายงานวิศวกรรมศาสตร์และเทคโนโลยีสารสนเทศ (สงวท.) | B22: ห้องไฟฟ้า 301 | D22: อุปกรณ์กระจายสัญญาณเครือข่ายแบบที่ 4 (Access Switch Type 4) | E22: Cisco /C9300L-24UXG-4X | F22: 4 | G22: 4 | N22: 4 | O22: 4 | P22: 4 | Q22: =IF($G22=0,1,(N22+O22+P22)/($G22*3)) -> 1 | S22: =IF(ISNUMBER(SEARCH("Access Point",D22)),"AP",IF(OR(ISNUMBER(SEARCH("Switch",D22)),ISNUMBER(SEARCH("Control Type",D22))),"Switch","Infra")) -> Switch | T22: =$H$21 -> 46071 | U22: =$J$21 -> 46071 | V22: =$I$21 -> 46073
A23: อาคารสายงานวิศวกรรมศาสตร์และเทคโนโลยีสารสนเทศ (สงวท.) | B23: ห้องไฟฟ้า ชั้น 4 | C23: 4 | D23: อุปกรณ์กระจายสัญญาณเครือข่ายแบบที่ 2 (Access Switch Type 2) | E23: Cisco /C9300L-24T-4X | F23: 0 | G23: 1 | H23: 46073 | I23: 46074 | J23: 46073 | K23: 46073 | L23: Complete | M23: ชื่อห้องเดิมคือ ห้องข้างๆ ลิฟ ชั้น 4 เพิ่ม 2 ตัวType 4 จากอาคารลานจอด ห้องวิศวกรรม Type 2 ย้ายจากชั้น 1 สงวท. | N23: 1 | O23: 1 | P23: 1 | Q23: =IF($G23=0,1,(N23+O23+P23)/($G23*3)) -> 1 | S23: =IF(ISNUMBER(SEARCH("Access Point",D23)),"AP",IF(OR(ISNUMBER(SEARCH("Switch",D23)),ISNUMBER(SEARCH("Control Type",D23))),"Switch","Infra")) -> Switch | T23: =$H$23 -> 46073 | U23: =$J$23 -> 46073 | V23: =$I$23 -> 46074
A24: อาคารสายงานวิศวกรรมศาสตร์และเทคโนโลยีสารสนเทศ (สงวท.) | B24: ห้องไฟฟ้า ชั้น 4 | D24: อุปกรณ์กระจายสัญญาณเครือข่ายแบบที่ 4 (Access Switch Type 4) | E24: Cisco /C9300L-24UXG-4X | F24: 2 | G24: 3 | N24: 3 | O24: 3 | P24: 3 | Q24: =IF($G24=0,1,(N24+O24+P24)/($G24*3)) -> 1 | S24: =IF(ISNUMBER(SEARCH("Access Point",D24)),"AP",IF(OR(ISNUMBER(SEARCH("Switch",D24)),ISNUMBER(SEARCH("Control Type",D24))),"Switch","Infra")) -> Switch | T24: =$H$23 -> 46073 | U24: =$J$23 -> 46073 | V24: =$I$23 -> 46074
A25: อาคารสำนักงานใหญ่ | B25: ชั้น 1 ห้องเก็บของ สกหม. | C25: 1 | D25: อุปกรณ์กระจายสัญญาณเครือข่ายรองแบบที่ 3 (Distribute Switch Type 3) | E25: Cisco /C9407R | F25: 2 | G25: 2 | H25: 46076 | I25: 46075 | J25: 46076 | K25: 46076 | L25: Complete | M25: ชื่อห้องเดิมคือ ชั้น 1 ห้องเก็บของ ตรงข้ามห้องพักเจ้าหน้าที่ปรับอากาศ | N25: 2 | O25: 2 | P25: 2 | Q25: =IF($G25=0,1,(N25+O25+P25)/($G25*3)) -> 1 | S25: =IF(ISNUMBER(SEARCH("Access Point",D25)),"AP",IF(OR(ISNUMBER(SEARCH("Switch",D25)),ISNUMBER(SEARCH("Control Type",D25))),"Switch","Infra")) -> Switch | T25: =$H$25 -> 46076 | U25: =$J$25 -> 46076 | V25: =$I$25 -> 46075
A26: อาคารสำนักงานใหญ่ | B26: ชั้น 5 ห้องไฟฟ้า | C26: 5 | D26: อุปกรณ์กระจายสัญญาณเครือข่ายแบบที่ 2 (Access Switch Type 2) | E26: Cisco /C9300L-24T-4X | F26: 6 | G26: 6 | H26: 46090 | I26: 46092 | J26: 46094 | K26: 46094 | L26: Complete | N26: 6 | O26: 6 | P26: 6 | Q26: =IF($G26=0,1,(N26+O26+P26)/($G26*3)) -> 1 | S26: =IF(ISNUMBER(SEARCH("Access Point",D26)),"AP",IF(OR(ISNUMBER(SEARCH("Switch",D26)),ISNUMBER(SEARCH("Control Type",D26))),"Switch","Infra")) -> Switch | T26: =$H$26 -> 46090 | U26: =$J$26 -> 46094 | V26: =$I$26 -> 46092
A27: อาคารสำนักงานใหญ่ | B27: ชั้น 5 ห้องไฟฟ้า | D27: อุปกรณ์กระจายสัญญาณเครือข่ายแบบที่ 4 (Access Switch Type 4) | E27: Cisco /C9300L-24UXG-4X | F27: 1 | G27: 1 | J27: 46090 | K27: 46092 | L27: Complete | N27: 1 | O27: 1 | P27: 1 | Q27: =IF($G27=0,1,(N27+O27+P27)/($G27*3)) -> 1 | S27: =IF(ISNUMBER(SEARCH("Access Point",D27)),"AP",IF(OR(ISNUMBER(SEARCH("Switch",D27)),ISNUMBER(SEARCH("Control Type",D27))),"Switch","Infra")) -> Switch | T27: =$H$26 -> 46090 | U27: =$J$26 -> 46094 | V27: =$I$26 -> 46092
A28: อาคารสำนักงานใหญ่ | B28: ชั้น 2 ห้องไฟฟ้า | C28: 2 | D28: อุปกรณ์กระจายสัญญาณเครือข่ายแบบที่ 2 (Access Switch Type 2) | E28: Cisco /C9300L-24T-4X | F28: 5 | G28: 5 | H28: 46078 | I28: 46081 | J28: 46078 | K28: 46085 | L28: Complete | N28: 5 | O28: 5 | P28: 5 | Q28: =IF($G28=0,1,(N28+O28+P28)/($G28*3)) -> 1 | S28: =IF(ISNUMBER(SEARCH("Access Point",D28)),"AP",IF(OR(ISNUMBER(SEARCH("Switch",D28)),ISNUMBER(SEARCH("Control Type",D28))),"Switch","Infra")) -> Switch | T28: =$H$28 -> 46078 | U28: =$J$28 -> 46078 | V28: =$I$28 -> 46081
A29: อาคารสำนักงานใหญ่ | B29: ชั้น 2 ห้องไฟฟ้า | D29: อุปกรณ์กระจายสัญญาณเครือข่ายแบบที่ 4 (Access Switch Type 4) | E29: Cisco /C9300L-24UXG-4X | F29: 1 | G29: 1 | N29: 1 | O29: 1 | P29: 1 | Q29: =IF($G29=0,1,(N29+O29+P29)/($G29*3)) -> 1 | S29: =IF(ISNUMBER(SEARCH("Access Point",D29)),"AP",IF(OR(ISNUMBER(SEARCH("Switch",D29)),ISNUMBER(SEARCH("Control Type",D29))),"Switch","Infra")) -> Switch | T29: =$H$28 -> 46078 | U29: =$J$28 -> 46078 | V29: =$I$28 -> 46081
A30: อาคารสำนักงานใหญ่ | B30: ชั้น 4 ห้องไฟฟ้า | C30: 4 | D30: อุปกรณ์กระจายสัญญาณเครือข่ายแบบที่ 2 (Access Switch Type 2) | E30: Cisco /C9300L-24T-4X | F30: 5 | G30: 5 | H30: 46083 | I30: 46086 | J30: 46087 | K30: 46087 | L30: Complete | M30: นำมาจากห้องสำนักเลขาชั้น 5 1 ตัว | N30: 5 | O30: 5 | P30: 5 | Q30: =IF($G30=0,1,(N30+O30+P30)/($G30*3)) -> 1 | S30: =IF(ISNUMBER(SEARCH("Access Point",D30)),"AP",IF(OR(ISNUMBER(SEARCH("Switch",D30)),ISNUMBER(SEARCH("Control Type",D30))),"Switch","Infra")) -> Switch | T30: =$H$30 -> 46083 | U30: =$J$30 -> 46087 | V30: =$I$30 -> 46086
A31: อาคารสำนักงานใหญ่ | B31: ชั้น 4 ห้องไฟฟ้า | D31: อุปกรณ์กระจายสัญญาณเครือข่ายแบบที่ 4 (Access Switch Type 4) | E31: Cisco /C9300L-24UXG-4X | F31: 1 | G31: 2 | K31: 46087 | N31: 2 | O31: 2 | P31: 2 | Q31: =IF($G31=0,1,(N31+O31+P31)/($G31*3)) -> 1 | S31: =IF(ISNUMBER(SEARCH("Access Point",D31)),"AP",IF(OR(ISNUMBER(SEARCH("Switch",D31)),ISNUMBER(SEARCH("Control Type",D31))),"Switch","Infra")) -> Switch | T31: =$H$30 -> 46083 | U31: =$J$30 -> 46087 | V31: =$I$30 -> 46086
A32: อาคารสำนักงานใหญ่ | B32: ชั้น 1 ห้องไฟฟ้า | C32: 1 | D32: อุปกรณ์กระจายสัญญาณเครือข่ายแบบที่ 2 (Access Switch Type 2) | E32: Cisco /C9300L-24T-4X | F32: 4 | G32: 4 | H32: 46076 | I32: 46079 | J32: 46076 | K32: 46080 | L32: Complete | N32: 4 | O32: 4 | P32: 4 | Q32: =IF($G32=0,1,(N32+O32+P32)/($G32*3)) -> 1 | S32: =IF(ISNUMBER(SEARCH("Access Point",D32)),"AP",IF(OR(ISNUMBER(SEARCH("Switch",D32)),ISNUMBER(SEARCH("Control Type",D32))),"Switch","Infra")) -> Switch | T32: =$H$32 -> 46076 | U32: =$J$32 -> 46076 | V32: =$I$32 -> 46079
A33: อาคารสำนักงานใหญ่ | B33: ชั้น 1 ห้องไฟฟ้า | D33: อุปกรณ์กระจายสัญญาณเครือข่ายแบบที่ 4 (Access Switch Type 4) | E33: Cisco /C9300L-24UXG-4X | F33: 1 | G33: 1 | N33: 1 | O33: 1 | P33: 1 | Q33: =IF($G33=0,1,(N33+O33+P33)/($G33*3)) -> 1 | S33: =IF(ISNUMBER(SEARCH("Access Point",D33)),"AP",IF(OR(ISNUMBER(SEARCH("Switch",D33)),ISNUMBER(SEARCH("Control Type",D33))),"Switch","Infra")) -> Switch | T33: =$H$32 -> 46076 | U33: =$J$32 -> 46076 | V33: =$I$32 -> 46079
A34: อาคารสำนักงานใหญ่ | B34: ชั้น 3 ห้องไฟฟ้า | C34: 3 | D34: อุปกรณ์กระจายสัญญาณเครือข่ายแบบที่ 2 (Access Switch Type 2) | E34: Cisco /C9300L-24T-4X | F34: 4 | G34: 5 | H34: 46080 | I34: 46083 | J34: 46080 | K34: 46087 | L34: Complete | M34: ย้ายtype 2 มาจากชั้น 2 ฝ่ายอำนวยการกลาง | N34: 5 | O34: 5 | P34: 5 | Q34: =IF($G34=0,1,(N34+O34+P34)/($G34*3)) -> 1 | S34: =IF(ISNUMBER(SEARCH("Access Point",D34)),"AP",IF(OR(ISNUMBER(SEARCH("Switch",D34)),ISNUMBER(SEARCH("Control Type",D34))),"Switch","Infra")) -> Switch | T34: =$H$34 -> 46080 | U34: =$J$34 -> 46080 | V34: =$I$34 -> 46083
A35: อาคารสำนักงานใหญ่ | B35: ชั้น 3 ห้องไฟฟ้า | D35: อุปกรณ์กระจายสัญญาณเครือข่ายแบบที่ 4 (Access Switch Type 4) | E35: Cisco /C9300L-24UXG-4X | F35: 1 | G35: 1 | N35: 1 | O35: 1 | P35: 1 | Q35: =IF($G35=0,1,(N35+O35+P35)/($G35*3)) -> 1 | S35: =IF(ISNUMBER(SEARCH("Access Point",D35)),"AP",IF(OR(ISNUMBER(SEARCH("Switch",D35)),ISNUMBER(SEARCH("Control Type",D35))),"Switch","Infra")) -> Switch | T35: =$H$34 -> 46080 | U35: =$J$34 -> 46080 | V35: =$I$34 -> 46083
A36: อาคารสำนักงานใหญ่ | B36: ชั้น 2 ห้องไฟฟ้า | C36: 2 | D36: อุปกรณ์กระจายสัญญาณเครือข่ายแบบที่ 2 (Access Switch Type 2) | E36: Cisco /C9300L-24T-4X | F36: 3 | G36: 4 | H36: 46078 | I36: 46081 | J36: 46078 | K36: 46087 | L36: Complete | M36: ชื่อห้องเดิมคือ HQ-AHU-203 เพิ่ม 1 ตัว จากห้อง ฝ่ายอำนวยกลาง | N36: 4 | O36: 4 | P36: 4 | Q36: =IF($G36=0,1,(N36+O36+P36)/($G36*3)) -> 1 | S36: =IF(ISNUMBER(SEARCH("Access Point",D36)),"AP",IF(OR(ISNUMBER(SEARCH("Switch",D36)),ISNUMBER(SEARCH("Control Type",D36))),"Switch","Infra")) -> Switch | T36: =$H$36 -> 46078 | U36: =$J$36 -> 46078 | V36: =$I$36 -> 46081
A37: อาคารสำนักงานใหญ่ | B37: ชั้น 3 ห้องไฟฟ้า | C37: 3 | D37: อุปกรณ์กระจายสัญญาณเครือข่ายแบบที่ 2 (Access Switch Type 2) | E37: Cisco /C9300L-24T-4X | F37: 3 | G37: 3 | H37: 46080 | I37: 46083 | J37: 46080 | K37: 46087 | L37: Complete | M37: ชื่อห้องเดิมคือ HQ-AHU-302 | N37: 3 | O37: 3 | P37: 3 | Q37: =IF($G37=0,1,(N37+O37+P37)/($G37*3)) -> 1 | S37: =IF(ISNUMBER(SEARCH("Access Point",D37)),"AP",IF(OR(ISNUMBER(SEARCH("Switch",D37)),ISNUMBER(SEARCH("Control Type",D37))),"Switch","Infra")) -> Switch | T37: =$H$37 -> 46080 | U37: =$J$37 -> 46080 | V37: =$I$37 -> 46083
A38: อาคารสำนักงานใหญ่ | B38: ชั้น 3 ห้องไฟฟ้า | D38: อุปกรณ์กระจายสัญญาณเครือข่ายแบบที่ 4 (Access Switch Type 4) | E38: Cisco /C9300L-24UXG-4X | F38: 1 | G38: 1 | N38: 1 | O38: 1 | P38: 1 | Q38: =IF($G38=0,1,(N38+O38+P38)/($G38*3)) -> 1 | S38: =IF(ISNUMBER(SEARCH("Access Point",D38)),"AP",IF(OR(ISNUMBER(SEARCH("Switch",D38)),ISNUMBER(SEARCH("Control Type",D38))),"Switch","Infra")) -> Switch | T38: =$H$37 -> 46080 | U38: =$J$37 -> 46080 | V38: =$I$39 -> 46092
A39: อาคารสำนักงานใหญ่ | B39: ชั้น 5 ห้องไฟฟ้า | C39: 5 | D39: อุปกรณ์กระจายสัญญาณเครือข่ายแบบที่ 2 (Access Switch Type 2) | E39: Cisco /C9300L-24T-4X | F39: 3 | G39: 3 | H39: 46090 | I39: 46092 | J39: 46090 | K39: 46092 | L39: Complete | M39: ชื่อห้องเดิมคือ ห้องควบคุมระบบไฟฟ้า ชั้น 5 ข้างห้องน้ำชาย | N39: 3 | O39: 3 | P39: 3 | Q39: =IF($G39=0,1,(N39+O39+P39)/($G39*3)) -> 1 | S39: =IF(ISNUMBER(SEARCH("Access Point",D39)),"AP",IF(OR(ISNUMBER(SEARCH("Switch",D39)),ISNUMBER(SEARCH("Control Type",D39))),"Switch","Infra")) -> Switch | T39: =$H$39 -> 46090 | U39: =$J$39 -> 46090 | V39: =$I$40 -> 46098
A40: อาคารสำนักงานใหญ่ | B40: ชั้น 6 ห้องไฟฟ้า | C40: 6 | D40: อุปกรณ์กระจายสัญญาณเครือข่ายแบบที่ 2 (Access Switch Type 2) | E40: Cisco /C9300L-24T-4X | F40: 2 | G40: 3 | H40: 46097 | I40: 46098 | J40: 46097 | K40: 46098 | L40: Complete | N40: 3 | O40: 3 | P40: 3 | Q40: =IF($G40=0,1,(N40+O40+P40)/($G40*3)) -> 1 | S40: =IF(ISNUMBER(SEARCH("Access Point",D40)),"AP",IF(OR(ISNUMBER(SEARCH("Switch",D40)),ISNUMBER(SEARCH("Control Type",D40))),"Switch","Infra")) -> Switch | T40: =$H$40 -> 46097 | U40: =$J$40 -> 46097 | V40: =$I$41 -> 46098
...

Sheet HQ-WL
A1: สถานที่ | B1: ชั้น | C1: ห้อง | D1: จำนวน | E1: Replace | F1: New Inst. | G1: New Cabling | H1: Migration Plan | I1: Install Date | J1: Complete Date | K1: จำนวน | L1: Replace | M1: New Inst. | N1: New Cabling | O1: Configuration | P1: Installation | Q1: Migration | R1: Total | S1: Remark | T1: วันที่เริ่ม (Helper)
A2: อาคารสำนักงานใหญ่ | B2: 1 | C2: ห้องประกวดราคา 115 | D2: 1 | E2: 1 | F2: 0 | G2: Done | H2: 244403 | K2: 1 | L2: 1 | M2: 0 | N2: Done | O2: 1 | P2: 1 | Q2: 1 | R2: =ROUNDUP(((O2+P2+Q2)/3)/K2*100%,2) -> 1 | T2: =$H$2 -> 244403
C3: สำนักงานฝ่ายพัสดุ | D3: 1 | E3: 1 | F3: 0 | G3: Done | K3: 1 | L3: 1 | M3: 0 | N3: Done | O3: 1 | P3: 1 | Q3: 1 | R3: =ROUNDUP(((O3+P3+Q3)/3)/K3*100%,2) -> 1 | T3: =$H$2 -> 244403
C4: ส่วนสัญญาและตรวจรับพัสดุ | D4: 1 | E4: 1 | F4: 0 | G4: Done | K4: 1 | L4: 1 | M4: 0 | N4: Done | O4: 1 | P4: 1 | Q4: 1 | R4: =ROUNDUP(((O4+P4+Q4)/3)/K4*100%,2) -> 1 | T4: =$H$2 -> 244403
C5: ธุรการ ฝ่ายอำนวยการกลาง | D5: 1 | E5: 1 | F5: 0 | G5: Done | K5: 1 | L5: 1 | M5: 0 | N5: Done | O5: 1 | P5: 1 | Q5: 1 | R5: =ROUNDUP(((O5+P5+Q5)/3)/K5*100%,2) -> 1 | T5: =$H$2 -> 244403
C6: ศูนย์รับ-ส่งหนังสือภายใน ทอท. | D6: 1 | E6: 1 | F6: 0 | G6: Done | K6: 1 | L6: 1 | M6: 0 | N6: Done | O6: 1 | P6: 1 | Q6: 1 | R6: =ROUNDUP(((O6+P6+Q6)/3)/K6*100%,2) -> 1 | T6: =$H$2 -> 244403
C7: โถงทางเดินทางไปลิฟท์ | D7: 1 | E7: 1 | F7: 0 | G7: Done | K7: 1 | L7: 1 | M7: 0 | N7: Done | O7: 1 | P7: 1 | Q7: 1 | R7: =ROUNDUP(((O7+P7+Q7)/3)/K7*100%,2) -> 1 | T7: =$H$2 -> 244403
C8: ห้องควบคุมระบบไฟฟ้า | D8: 1 | E8: 1 | F8: 0 | G8: Done | K8: 1 | L8: 1 | M8: 0 | N8: Done | O8: 1 | P8: 1 | Q8: 1 | R8: =ROUNDUP(((O8+P8+Q8)/3)/K8*100%,2) -> 1 | T8: =$H$2 -> 244403
C9: ฝ่ายการเงิน (กองการเงิน) | D9: 1 | E9: 1 | F9: 0 | G9: Done | K9: 1 | L9: 1 | M9: 0 | N9: Done | O9: 1 | P9: 1 | Q9: 1 | R9: =ROUNDUP(((O9+P9+Q9)/3)/K9*100%,2) -> 1 | T9: =$H$2 -> 244403
C10: ฝ่ายการเงิน (กองการบัญชี) | D10: 1 | E10: 1 | F10: 0 | G10: Done | K10: 1 | L10: 1 | M10: 0 | N10: Done | O10: 1 | P10: 1 | Q10: 1 | R10: =ROUNDUP(((O10+P10+Q10)/3)/K10*100%,2) -> 1 | T10: =$H$2 -> 244403
B11: 2 | C11: ฝ่ายอำนวยการกลาง สำนักงานบัญชีพัสดุ | D11: 2 | E11: 2 | F11: 0 | G11: Done | H11: 46082 | K11: 2 | L11: 2 | M11: 0 | N11: Done | O11: 2 | P11: 2 | Q11: 2 | R11: =ROUNDUP(((O11+P11+Q11)/3)/K11*100%,2) -> 1 | T11: =$H$11 -> 46082
C12: ฝ่ายอำนวยการกลาง งานบริหารทั่วไป | D12: 1 | E12: 1 | F12: 0 | G12: Done | K12: 1 | L12: 1 | M12: 0 | N12: Done | O12: 1 | P12: 1 | Q12: 1 | R12: =ROUNDUP(((O12+P12+Q12)/3)/K12*100%,2) -> 1 | T12: =$H$11 -> 46082
C13: ฝ่ายอำนวยการกลาง ส่วนสนับสนุนผู้บริหาร | D13: 1 | E13: 1 | F13: 0 | G13: Done | K13: 1 | L13: 1 | M13: 0 | N13: Done | O13: 1 | P13: 1 | Q13: 1 | R13: =ROUNDUP(((O13+P13+Q13)/3)/K13*100%,2) -> 1 | T13: =$H$11 -> 46082
C14: ห้องประชุม ทอท.5 | D14: 1 | E14: 1 | F14: 0 | G14: Done | K14: 1 | L14: 1 | M14: 0 | N14: Done | O14: 1 | P14: 1 | Q14: 1 | R14: =ROUNDUP(((O14+P14+Q14)/3)/K14*100%,2) -> 1 | T14: =$H$11 -> 46082
C15: ฝ่ายสื่อสารองค์กร | D15: 2 | E15: 2 | F15: 0 | G15: Done | K15: 2 | L15: 2 | M15: 0 | N15: Done | O15: 2 | P15: 2 | Q15: 2 | R15: =ROUNDUP(((O15+P15+Q15)/3)/K15*100%,2) -> 1 | T15: =$H$11 -> 46082
C16: สำนักงานตรวจเงินแผ่นดิน | D16: 1 | E16: 1 | F16: 0 | G16: Done | K16: 1 | L16: 1 | M16: 0 | N16: Done | O16: 1 | P16: 1 | Q16: 1 | R16: =ROUNDUP(((O16+P16+Q16)/3)/K16*100%,2) -> 1 | T16: =$H$11 -> 46082
C17: รองผู้อำนวยการฝ่ายบัญชี | D17: 1 | E17: 1 | F17: 0 | G17: Done | K17: 1 | L17: 1 | M17: 0 | N17: Done | O17: 1 | P17: 1 | Q17: 1 | R17: =ROUNDUP(((O17+P17+Q17)/3)/K17*100%,2) -> 1 | T17: =$H$11 -> 46082
C18: ฝ่ายบัญชี (งานการเงิน) | D18: 1 | E18: 1 | F18: 0 | G18: Done | K18: 1 | L18: 1 | M18: 0 | N18: Done | O18: 1 | P18: 1 | Q18: 1 | R18: =ROUNDUP(((O18+P18+Q18)/3)/K18*100%,2) -> 1 | T18: =$H$11 -> 46082
C19: ฝ่ายบัญชี (งานบริหารทั่วไป) | D19: 1 | E19: 1 | F19: 0 | G19: Done | K19: 1 | L19: 1 | M19: 0 | N19: Done | O19: 1 | P19: 1 | Q19: 1 | R19: =ROUNDUP(((O19+P19+Q19)/3)/K19*100%,2) -> 1 | T19: =$H$11 -> 46082
C20: โถงหน้าลิฟต์ | D20: 1 | E20: 1 | F20: 0 | G20: Done | K20: 1 | L20: 1 | M20: 0 | N20: Done | O20: 1 | P20: 1 | Q20: 1 | R20: =ROUNDUP(((O20+P20+Q20)/3)/K20*100%,2) -> 1 | T20: =$H$11 -> 46082
C21: ฝ่ายบัญชี (งานบัญชีลูกหนี้) | D21: 1 | E21: 1 | F21: 0 | G21: Done | K21: 1 | L21: 1 | M21: 0 | N21: Done | O21: 1 | P21: 1 | Q21: 1 | R21: =ROUNDUP(((O21+P21+Q21)/3)/K21*100%,2) -> 1 | T21: =$H$11 -> 46082
C22: โถงทางเดินเชื่อม | D22: 2 | E22: 2 | F22: 0 | G22: Done | K22: 2 | L22: 2 | M22: 0 | N22: Done | O22: 2 | P22: 2 | Q22: 2 | R22: =ROUNDUP(((O22+P22+Q22)/3)/K22*100%,2) -> 1 | T22: =$H$11 -> 46082
C23: สำนักงาน | D23: 1 | E23: 0 | F23: 1 | G23: Done | K23: 1 | L23: 0 | M23: 1 | N23: Done | O23: 1 | P23: 1 | Q23: 1 | R23: =ROUNDUP(((O23+P23+Q23)/3)/K23*100%,2) -> 1 | T23: =$H$11 -> 46082
... C26: หน้าห้องผู้อำนวยการฝ่ายพัสดุ | D26: 1 | E26: 0 | F26: 1 | G26: Done | K26: 1 | L26: 0 | M26: 1 | N26: Done | O26: 1 | P26: 1 | Q26: 1 | R26: =ROUNDUP(((O26+P26+Q26)/3)/K26*100%,2) -> 1 | T26: =$H$11 -> 46082
B27: 3 | C27: ฝ่ายกำกับกฎระเบียบองค์กรและป้องกันการทุจริต | D27: 1 | E27: 1 | F27: 0 | G27: Done | H27: 46085 | K27: 1 | L27: 1 | M27: 0 | N27: Done | O27: 1 | P27: 1 | Q27: 1 | R27: =ROUNDUP(((O27+P27+Q27)/3)/K27*100%,2) -> 1 | T27: =$H$27 -> 46085
C28: ห้องฝึกอบรม 1 (ส่วนพัฒนาดิจิทัลองค์กร) | D28: 1 | E28: 1 | F28: 0 | G28: Done | K28: 1 | L28: 1 | M28: 0 | N28: Done | O28: 1 | P28: 1 | Q28: 1 | R28: =ROUNDUP(((O28+P28+Q28)/3)/K28*100%,2) -> 1 | T28: =$H$27 -> 46085
C29: หน้าห้องฝึกอบรม 1 (ส่วนพัฒนาดิจิทัลองค์กร) | D29: 1 | E29: 1 | F29: 0 | G29: Done | K29: 1 | L29: 1 | M29: 0 | N29: Done | O29: 1 | P29: 1 | Q29: 1 | R29: =ROUNDUP(((O29+P29+Q29)/3)/K29*100%,2) -> 1 | T29: =$H$27 -> 46085
C30: โถงทางเดินหน้าลิฟต์ | D30: 1 | E30: 1 | F30: 0 | G30: Done | K30: 1 | L30: 1 | M30: 0 | N30: Done | O30: 1 | P30: 1 | Q30: 1 | R30: =ROUNDUP(((O30+P30+Q30)/3)/K30*100%,2) -> 1 | T30: =$H$27 -> 46085
C31: โถงทางเดิน หน้าห้องถ่ายบัตรพนักงาน | D31: 1 | E31: 1 | F31: 0 | G31: Done | K31: 1 | L31: 1 | M31: 0 | N31: Done | O31: 1 | P31: 1 | Q31: 1 | R31: =ROUNDUP(((O31+P31+Q31)/3)/K31*100%,2) -> 1 | T31: =$H$27 -> 46085
C32: สำนักงาน ฝ่ายพัฒนาทรัพยากรบุคคล | D32: 5 | E32: 5 | F32: 0 | G32: Done | K32: 5 | L32: 5 | M32: 0 | N32: Done | O32: 5 | P32: 5 | Q32: 5 | R32: =ROUNDUP(((O32+P32+Q32)/3)/K32*100%,2) -> 1 | T32: =$H$27 -> 46085
C33: ห้องประชุมใหญ่ ทอท. (AOT AUDITORIUM) | D33: 3 | E33: 3 | F33: 0 | G33: Done | K33: 3 | L33: 3 | M33: 0 | N33: Done | O33: 3 | P33: 3 | Q33: 3 | R33: =ROUNDUP(((O33+P33+Q33)/3)/K33*100%,2) -> 1 | T33: =$H$27 -> 46085
C34: สำนักงาน | D34: 1 | E34: 0 | F34: 1 | G34: Done | K34: 1 | L34: 0 | M34: 1 | N34: Done | O34: 1 | P34: 1 | Q34: 1 | R34: =ROUNDUP(((O34+P34+Q34)/3)/K34*100%,2) -> 1 | T34: =$H$27 -> 46085
B35: 4 | C35: โถงทางเดิน สำนักตรวจสอบ | D35: 3 | E35: 3 | F35: 0 | G35: Done | H35: 46087 | K35: 3 | L35: 3 | M35: 0 | N35: Done | O35: 3 | P35: 3 | Q35: 3 | R35: =ROUNDUP(((O35+P35+Q35)/3)/K35*100%,2) -> 1 | T35: =$H$35 -> 46087
C36: สำนักงาน ฝ่ายกลยุทธองค์กร / ฝ่ายงบประมาณ | D36: 8 | E36: 8 | F36: 0 | G36: Done | K36: 8 | L36: 8 | M36: 0 | N36: Done | O36: 8 | P36: 8 | Q36: 8 | R36: =ROUNDUP(((O36+P36+Q36)/3)/K36*100%,2) -> 1 | T36: =$H$35 -> 46087
C37: โถงหน้าลิฟต์ | D37: 1 | E37: 1 | F37: 0 | G37: Done | K37: 1 | L37: 1 | M37: 0 | N37: Done | O37: 1 | P37: 1 | Q37: 1 | R37: =ROUNDUP(((O37+P37+Q37)/3)/K37*100%,2) -> 1 | T37: =$H$35 -> 46087
C38: สำนักงาน | D38: 2 | E38: 0 | F38: 2 | G38: Done | K38: 2 | L38: 0 | M38: 2 | N38: Done | O38: 2 | P38: 2 | Q38: 2 | R38: =ROUNDUP(((O38+P38+Q38)/3)/K38*100%,2) -> 1 | T38: =$H$35 -> 46087
B39: 5 | C39: สำนักงานเลขานุการบริษัท (งานบริหารทั่วไป) | D39: 1 | E39: 1 | F39: 0 | G39: Done | H39: 46090 | K39: 1 | L39: 1 | M39: 0 | N39: Done | O39: 1 | P39: 1 | Q39: 1 | R39: =ROUNDUP(((O39+P39+Q39)/3)/K39*100%,2) -> 1 | T39: =$H$39 -> 46090
C40: ส่วนกิจกรรมเชิงพาณิชย์ | D40: 1 | E40: 1 | F40: 0 | G40: Done | K40: 1 | L40: 1 | M40: 0 | N40: Done | O40: 1 | P40: 1 | Q40: 1 | R40: =ROUNDUP(((O40+P40+Q40)/3)/K40*100%,2) -> 1 | T40: =$H$39 -> 46090
C41: ส่วนบริหารธุรกิจ | D41: 1 | E41: 1 | F41: 0 | G41: Done | K41: 1 | L41: 1 | M41: 0 | N41: Done | O41: 1 | P41: 1 | Q41: 1 | R41: =ROUNDUP(((O41+P41+Q41)/3)/K41*100%,2) -> 1 | T41: =$H$39 -> 46090
C42: แผนกกลยุทธ์ธุรกิจ | D42: 1 | E42: 1 | F42: 0 | G42: Done | K42: 1 | L42: 1 | M42: 0 | N42: Done | O42: 1 | P42: 1 | Q42: 1 | R42: =ROUNDUP(((O42+P42+Q42)/3)/K42*100%,2) -> 1 | T42: =$H$39 -> 46090
...

Sheet HQ-PW
A1: Node | B1: สถานที่ | C1: ชั้น | D1: ชื่อห้อง | E1: ชื่อ Rack | F1: ติดตั้ง PDU 6 ช่อง | G1: ติดตั้ง PDU 8 ช่อง | H1: ติดตั้ง PDU 10 ช่อง | I1: ติดตั้ง PDU 12 ช่อง | J1: ติดตั้ง CB | K1: ใช้ Temp. PDU | L1: เปลี่ยนเต้ารับผนัง 2 ช่อง | M1: ตัดต่อปลั๊กใหม่ | N1: ตั้งตู้ Rack ใหม่ | O1: Pregress
A2: HQ | B2: อาคารสายงานวิศวกรรมศาสตร์และเทคโนโลยีสารสนเทศ (สงวท.) | C2: 2 | D2: ชั้น 2 Data Center | F2: FALSE | G2: FALSE | H2: FALSE | I2: TRUE | J2: TRUE | K2: FALSE | L2: FALSE | M2: FALSE | N2: FALSE | O2: Done
A3: HQ | B3: อาคารสายงานวิศวกรรมศาสตร์และเทคโนโลยีสารสนเทศ (สงวท.) | C3: 1 | D3: ห้องไฟฟ้า 102 | E3: 27U , IT1 (27U) | F3: TRUE | G3: FALSE | H3: FALSE | I3: TRUE | J3: FALSE | K3: FALSE | L3: FALSE | M3: FALSE | N3: FALSE | O3: Done
A4: HQ | B4: อาคารสายงานวิศวกรรมศาสตร์และเทคโนโลยีสารสนเทศ (สงวท.) | C4: 2 | D4: ชั้น 2 ห้องฝ่ายระบบคอมพิวเตอร์และเครือข่าย ห้องเก็บของ | F4: FALSE | G4: FALSE | H4: FALSE | I4: TRUE | J4: FALSE | K4: FALSE | L4: TRUE | M4: FALSE | N4: FALSE | O4: Done
A5: HQ | B5: อาคารสายงานวิศวกรรมศาสตร์และเทคโนโลยีสารสนเทศ (สงวท.) | C5: 3 | D5: ห้องไฟฟ้า 301 | F5: TRUE | G5: FALSE | H5: FALSE | I5: TRUE | J5: TRUE | K5: FALSE | L5: FALSE | M5: FALSE | N5: FALSE | O5: Done
A6: HQ | B6: อาคารสายงานวิศวกรรมศาสตร์และเทคโนโลยีสารสนเทศ (สงวท.) | C6: 4 | D6: ห้องข้างๆ ลิฟ ชั้น 4 ห้องไฟฟ้า ชั้น 4 | F6: FALSE | G6: FALSE | H6: FALSE | I6: TRUE | J6: TRUE | K6: FALSE | L6: FALSE | M6: FALSE | N6: FALSE | O6: Done
A7: HQ | B7: อาคารสำนักงานใหญ่ | C7: 1 | D7: ชั้น 1 ห้องเก็บของ ตรงข้ามห้องพักเจ้าหน้าที่ปรับอากาศ ชั้น 1 ห้องเก็บของ สกหม. | F7: TRUE | G7: FALSE | H7: FALSE | I7: TRUE | J7: TRUE | K7: FALSE | L7: FALSE | M7: FALSE | N7: TRUE | O7: Done
A8: HQ | B8: อาคารสำนักงานใหญ่ | C8: 2 | D8: HQ-AHU-203 ชั้น 2 ห้องไฟฟ้า | F8: TRUE | G8: FALSE | H8: FALSE | I8: TRUE | J8: FALSE | K8: FALSE | L8: FALSE | M8: FALSE | N8: FALSE | O8: Done
A9: HQ | B9: อาคารสำนักงานใหญ่ | C9: 3 | D9: HQ-AHU-302 ชั้น 3 ห้องไฟฟ้า | F9: FALSE | G9: FALSE | H9: FALSE | I9: TRUE | J9: FALSE | K9: FALSE | L9: FALSE | M9: FALSE | N9: FALSE | O9: Done
A10: HQ | B10: อาคารสำนักงานใหญ่ | C10: 6 | D10: ชั้น 6 ห้องไฟฟ้า | F10: FALSE | G10: FALSE | H10: FALSE | I10: TRUE | J10: FALSE | K10: FALSE | L10: FALSE | M10: FALSE | N10: FALSE | O10: Done
A11: HQ | B11: อาคารสำนักงานใหญ่ | C11: 1 | D11: HQ-AHU-127 ชั้น 1 ห้องไฟฟ้า | F11: FALSE | G11: FALSE | H11: FALSE | I11: TRUE | J11: FALSE | K11: FALSE | L11: FALSE | M11: FALSE | N11: FALSE | O11: Done
A12: HQ | B12: อาคารสำนักงานใหญ่ | C12: 1 | D12: ห้องฝ่ายการเงิน | F12: TRUE | G12: FALSE | H12: FALSE | I12: FALSE | J12: FALSE | K12: FALSE | L12: TRUE | M12: FALSE | N12: FALSE | O12: Done
A13: HQ | B13: อาคารสำนักงานใหญ่ | C13: 5 | D13: สำนักงานเลขานุการบริษัทฝ่ายป้องกันอุบัติภัยและอาชีวอนามัย | F13: FALSE | G13: FALSE | H13: FALSE | I13: TRUE | J13: FALSE | K13: FALSE | L13: FALSE | M13: FALSE | N13: FALSE | O13: Done
A14: HQ | B14: อาคารสำนักงานใหญ่ | C14: 2 | D14: ฝ่ายบัญชี | F14: TRUE | G14: FALSE | H14: FALSE | I14: FALSE | J14: FALSE | K14: FALSE | L14: FALSE | M14: FALSE | N14: FALSE | O14: Done
A15: HQ | B15: อาคารสำนักงานใหญ่ | C15: 3 | D15: ฝ่ายพัฒนาทรัพยากรบุคคล | F15: FALSE | G15: FALSE | H15: FALSE | I15: TRUE | J15: FALSE | K15: FALSE | L15: FALSE | M15: FALSE | N15: FALSE | O15: Done
... A29: HQ | B29: อาคารบำบัดน้ำเสีย | C29: 1 | D29: สำนักงาน | F29: FALSE | G29: FALSE | H29: FALSE | I29: TRUE | J29: FALSE | K29: FALSE | L29: FALSE | M29: FALSE | N29: FALSE | O29: Done
A30: HQ | B30: อาคารเสริมสร้างพลานามัย | C30: 1 | D30: ห้อง SIS ห้องเก็บของ | E30: - | F30: TRUE | G30: FALSE | H30: FALSE | I30: FALSE | J30: FALSE | K30: FALSE | L30: FALSE | M30: FALSE | N30: FALSE | O30: Done
A31: HQ | B31: อาคารเสริมสร้างพลานามัย | C31: 1 | D31: ห้องกีฬาอเนกประสงค์ 2 ห้องสำนักงานสมาคมสโมสรท่าอากาศยาน | E31: - | F31: TRUE | G31: FALSE | H31: FALSE | I31: FALSE | J31: FALSE | K31: FALSE | L31: FALSE | M31: FALSE | N31: FALSE | O31: Done
A32: HQ | B32: สถานีไฟฟ้าย่อย 1 อาคารข้างหน้า | C32: 1 | D32: ห้องไฟฟ้า ห้องแบตเตอรี่ | E32: - | F32: TRUE | G32: FALSE | H32: FALSE | I32: FALSE | J32: FALSE | K32: FALSE | L32: FALSE | M32: FALSE | N32: FALSE | O32: Done
B33: =COUNTIF(Table224[สถานที่],"*") -> 31 | D33: =COUNTIF(Table224[ชื่อห้อง],"*") -> 31 | E33: สรุปจำนวน | F33: =(COUNTIF(F2:F32, TRUE)) -> 14 | G33: =COUNTIF(G2:G32, TRUE) -> 0 | H33: =COUNTIF(H2:H32, TRUE) -> 0 | I33: =(COUNTIF(I2:I32, TRUE)) -> 23 | J33: =(COUNTIF(J2:J32,TRUE)) -> 4 | K33: =COUNTIF(K2:K32, TRUE) -> 0 | L33: =COUNTIF(L2:L32, TRUE) -> 3 | M33: =COUNTIF(M2:M32, TRUE) -> 0 | N33: =COUNTIF(N2:N32, TRUE) -> 3 | O33: =COUNTIF(Table224[Pregress],"Done") -> 31

Sheet HQ-รายสัปดาห์
A1: สรุปแผนความก้าวหน้ารายสัปดาห์ - สนญ. (HQ)
A2: แผนการติดตั้งและ Migration เปรียบเทียบแผนกับผลจริง (เป้าหมาย 100%) | สูตรดึงข้อมูลอัตโนมัติจาก sheet HQ
A4: รายการ | B4: W.1 (2/2-8/2) | C4: W.2 (9/2-15/2) | D4: W.3 (16/2-22/2) | E4: W.4 (23/2-1/3) | F4: W.5 (2/3-8/3) | G4: W.6 (9/3-15/3) | H4: W.7 (16/3-22/3) | I4: W.8 (23/3-29/3) | J4: W.9 (30/3-5/4) | K4: W.10 (6/4-12/4) | L4: W.11 (13/4-19/4) | M4: W.12 (20/4-26/4) | N4: W.13 (27/4-3/5) | O4: W.14 (4/5-10/5) | P4: รวมทั้งหมด
A6: ▌ จำนวนอุปกรณ์ที่วางแผนติดตั้ง-Migration (เครื่อง)
A7: จำนวนอุปกรณ์ตามแผน (เครื่อง) | B7: {=SUMPRODUCT((HQ!$T$3:$T$89>=B40)*(HQ!$T$3:$T$89<=B41)*(ISNUMBER(HQ!$G$3:$G$89))*(HQ!$G$3:$G$89))} -> 34 | C7: {=SUMPRODUCT((HQ!$T$3:$T$89>=C40)*(HQ!$T$3:$T$89<=C41)*(ISNUMBER(HQ!$G$3:$G$89))*(HQ!$G$3:$G$89))} -> 10 | D7: {=SUMPRODUCT((HQ!$T$3:$T$89>=D40)*(HQ!$T$3:$T$89<=D41)*(ISNUMBER(HQ!$G$3:$G$89))*(HQ!$G$3:$G$89))} -> 9 | E7: {=SUMPRODUCT((HQ!$T$3:$T$89>=E40)*(HQ!$T$3:$T$89<=E41)*(ISNUMBER(HQ!$G$3:$G$89))*(HQ!$G$3:$G$89))} -> 52 | F7: {=SUMPRODUCT((HQ!$T$3:$T$89>=F40)*(HQ!$T$3:$T$89<=F41)*(ISNUMBER(HQ!$G$3:$G$89))*(HQ!$G$3:$G$89))} -> 14 | G7: {=SUMPRODUCT((HQ!$T$3:$T$89>=G40)*(HQ!$T$3:$T$89<=G41)*(ISNUMBER(HQ!$G$3:$G$89))*(HQ!$G$3:$G$89))} -> 18 | H7: {=SUMPRODUCT((HQ!$T$3:$T$89>=H40)*(HQ!$T$3:$T$89<=H41)*(ISNUMBER(HQ!$G$3:$G$89))*(HQ!$G$3:$G$89))} -> 11 | I7: {=SUMPRODUCT((HQ!$T$3:$T$89>=I40)*(HQ!$T$3:$T$89<=I41)*(ISNUMBER(HQ!$G$3:$G$89))*(HQ!$G$3:$G$89))} -> 15 | ... O7: {=SUMPRODUCT((HQ!$T$3:$T$89>=O40)*(HQ!$T$3:$T$89<=O41)*(ISNUMBER(HQ!$G$3:$G$89))*(HQ!$G$3:$G$89))} -> 0 | P7: {=SUMPRODUCT((ISNUMBER(HQ!$G$3:$G$89))*(HQ!$G$3:$G$89))} -> 193
A8: % แผนรายสัปดาห์ (ของยอดรวม) | B8: =IF(B7=0,"-",B7/$P$7) -> 0.1761658 | C8: =IF(C7=0,"-",C7/$P$7) -> 0.051813472 | D8: =IF(D7=0,"-",D7/$P$7) -> 0.046632124 | E8: =IF(E7=0,"-",E7/$P$7) -> 0.26943005 | F8: =IF(F7=0,"-",F7/$P$7) -> 0.07253886 | G8: =IF(G7=0,"-",G7/$P$7) -> 0.093264249 | H8: =IF(H7=0,"-",H7/$P$7) -> 0.056994819 | I8: =IF(I7=0,"-",I7/$P$7) -> 0.077720207 | ... O8: =IF(O7=0,"-",O7/$P$7) -> - | P8: =P7/P7 -> 1
A10: ▌ Configuration
A11: แผน (เครื่อง) | B11: =B7 -> 34 | C11: =C7 -> 10 | D11: =D7 -> 9 | E11: =E7 -> 52 | F11: =F7 -> 14 | G11: =G7 -> 18 | H11: =H7 -> 11 | I11: =I7 -> 15 | ... P11: =P7 -> 193
A12: ผลจริง (เครื่อง) | B12: {=SUMPRODUCT((HQ!$T$3:$T$89>=B40)*(HQ!$T$3:$T$89<=B41)*(ISNUMBER(HQ!$N$3:$N$89))*(HQ!$N$3:$N$89))} -> 30 | C12: {=SUMPRODUCT((HQ!$T$3:$T$89>=C40)*(HQ!$T$3:$T$89<=C41)*(ISNUMBER(HQ!$N$3:$N$89))*(HQ!$N$3:$N$89))} -> 10 | D12: {=SUMPRODUCT((HQ!$T$3:$T$89>=D40)*(HQ!$T$3:$T$89<=D41)*(ISNUMBER(HQ!$N$3:$N$89))*(HQ!$N$3:$N$89))} -> 9 | E12: {=SUMPRODUCT((HQ!$T$3:$T$89>=E40)*(HQ!$T$3:$T$89<=E41)*(ISNUMBER(HQ!$N$3:$N$89))*(HQ!$N$3:$N$89))} -> 52 | F12: {=SUMPRODUCT((HQ!$T$3:$T$89>=F40)*(HQ!$T$3:$T$89<=F41)*(ISNUMBER(HQ!$N$3:$N$89))*(HQ!$N$3:$N$89))} -> 14 | G12: {=SUMPRODUCT((HQ!$T$3:$T$89>=G40)*(HQ!$T$3:$T$89<=G41)*(ISNUMBER(HQ!$N$3:$N$89))*(HQ!$N$3:$N$89))} -> 18 | H12: {=SUMPRODUCT((HQ!$T$3:$T$89>=H40)*(HQ!$T$3:$T$89<=H41)*(ISNUMBER(HQ!$N$3:$N$89))*(HQ!$N$3:$N$89))} -> 11 | I12: {=SUMPRODUCT((HQ!$T$3:$T$89>=I40)*(HQ!$T$3:$T$89<=I41)*(ISNUMBER(HQ!$N$3:$N$89))*(HQ!$N$3:$N$89))} -> 15 | ... O12: {=SUMPRODUCT((HQ!$T$3:$T$89>=O40)*(HQ!$T$3:$T$89<=O41)*(ISNUMBER(HQ!$N$3:$N$89))*(HQ!$N$3:$N$89))} -> 0 | P12: =SUM(B12:O12) -> 188
A13: % ความก้าวหน้า Configuration | B13: =IF(B11=0,IF(B12=0,"-","100%"),B12/B11) -> 0.88235294 | C13: =IF(C11=0,IF(C12=0,"-","100%"),C12/C11) -> 1 | D13: =IF(D11=0,IF(D12=0,"-","100%"),D12/D11) -> 1 | E13: =IF(E11=0,IF(E12=0,"-","100%"),E12/E11) -> 1 | F13: =IF(F11=0,IF(F12=0,"-","100%"),F12/F11) -> 1 | G13: =IF(G11=0,IF(G12=0,"-","100%"),G12/G11) -> 1 | H13: =IF(H11=0,IF(H12=0,"-","100%"),H12/H11) -> 1 | I13: =IF(I11=0,IF(I12=0,"-","100%"),I12/I11) -> 1 | ... O13: =IF(O11=0,IF(O12=0,"-","100%"),O12/O11) -> - | P13: =IF(P11=0,"-",P12/P11) -> 0.97409326
A15: ▌ Installation
A16: แผน (เครื่อง) | B16: =B7 -> 34 | C16: =C7 -> 10 | D16: =D7 -> 9 | E16: =E7 -> 52 | F16: =F7 -> 14 | G16: =G7 -> 18 | H16: =H7 -> 11 | I16: =I7 -> 15 | ... P16: =P7 -> 193
A17: ผลจริง (เครื่อง) | B17: {=SUMPRODUCT((HQ!$T$3:$T$89>=B40)*(HQ!$T$3:$T$89<=B41)*(ISNUMBER(HQ!$O$3:$O$89))*(HQ!$O$3:$O$89))} -> 30 | C17: {=SUMPRODUCT((HQ!$T$3:$T$89>=C40)*(HQ!$T$3:$T$89<=C41)*(ISNUMBER(HQ!$O$3:$O$89))*(HQ!$O$3:$O$89))} -> 10 | D17: {=SUMPRODUCT((HQ!$T$3:$T$89>=D40)*(HQ!$T$3:$T$89<=D41)*(ISNUMBER(HQ!$O$3:$O$89))*(HQ!$O$3:$O$89))} -> 9 | E17: {=SUMPRODUCT((HQ!$T$3:$T$89>=E40)*(HQ!$T$3:$T$89<=E41)*(ISNUMBER(HQ!$O$3:$O$89))*(HQ!$O$3:$O$89))} -> 52 | F17: {=SUMPRODUCT((HQ!$T$3:$T$89>=F40)*(HQ!$T$3:$T$89<=F41)*(ISNUMBER(HQ!$O$3:$O$89))*(HQ!$O$3:$O$89))} -> 14 | G17: {=SUMPRODUCT((HQ!$T$3:$T$89>=G40)*(HQ!$T$3:$T$89<=G41)*(ISNUMBER(HQ!$O$3:$O$89))*(HQ!$O$3:$O$89))} -> 18 | H17: {=SUMPRODUCT((HQ!$T$3:$T$89>=H40)*(HQ!$T$3:$T$89<=H41)*(ISNUMBER(HQ!$O$3:$O$89))*(HQ!$O$3:$O$89))} -> 11 | I17: {=SUMPRODUCT((HQ!$T$3:$T$89>=I40)*(HQ!$T$3:$T$89<=I41)*(ISNUMBER(HQ!$O$3:$O$89))*(HQ!$O$3:$O$89))} -> 15 | ... O17: {=SUMPRODUCT((HQ!$T$3:$T$89>=O40)*(HQ!$T$3:$T$89<=O41)*(ISNUMBER(HQ!$O$3:$O$89))*(HQ!$O$3:$O$89))} -> 0 | P17: =SUM(B17:O17) -> 188
A18: % ความก้าวหน้า Installation | B18: =IF(B16=0,IF(B17=0,"-","100%"),B17/B16) -> 0.88235294 | C18: =IF(C16=0,IF(C17=0,"-","100%"),C17/C16) -> 1 | D18: =IF(D16=0,IF(D17=0,"-","100%"),D17/D16) -> 1 | E18: =IF(E16=0,IF(E17=0,"-","100%"),E17/E16) -> 1 | F18: =IF(F16=0,IF(F17=0,"-","100%"),F17/F16) -> 1 | G18: =IF(G16=0,IF(G17=0,"-","100%"),G17/G16) -> 1 | H18: =IF(H16=0,IF(H17=0,"-","100%"),H17/H16) -> 1 | I18: =IF(I16=0,IF(I17=0,"-","100%"),I17/I16) -> 1 | ... O18: =IF(O16=0,IF(O17=0,"-","100%"),O17/O16) -> - | P18: =IF(P16=0,"-",P17/P16) -> 0.97409326
A20: ▌ Migration
A21: แผน (เครื่อง) | B21: =B7 -> 34 | C21: =C7 -> 10 | D21: =D7 -> 9 | E21: =E7 -> 52 | F21: =F7 -> 14 | G21: =G7 -> 18 | H21: =H7 -> 11 | I21: =I7 -> 15 | ... P21: =P7 -> 193
A22: ผลจริง (เครื่อง) | B22: {=SUMPRODUCT((HQ!$T$3:$T$89>=B40)*(HQ!$T$3:$T$89<=B41)*(ISNUMBER(HQ!$P$3:$P$89))*(HQ!$P$3:$P$89))} -> 27 | C22: {=SUMPRODUCT((HQ!$T$3:$T$89>=C40)*(HQ!$T$3:$T$89<=C41)*(ISNUMBER(HQ!$P$3:$P$89))*(HQ!$P$3:$P$89))} -> 10 | D22: {=SUMPRODUCT((HQ!$T$3:$T$89>=D40)*(HQ!$T$3:$T$89<=D41)*(ISNUMBER(HQ!$P$3:$P$89))*(HQ!$P$3:$P$89))} -> 9 | E22: {=SUMPRODUCT((HQ!$T$3:$T$89>=E40)*(HQ!$T$3:$T$89<=E41)*(ISNUMBER(HQ!$P$3:$P$89))*(HQ!$P$3:$P$89))} -> 52 | F22: {=SUMPRODUCT((HQ!$T$3:$T$89>=F40)*(HQ!$T$3:$T$89<=F41)*(ISNUMBER(HQ!$P$3:$P$89))*(HQ!$P$3:$P$89))} -> 14 | G22: {=SUMPRODUCT((HQ!$T$3:$T$89>=G40)*(HQ!$T$3:$T$89<=G41)*(ISNUMBER(HQ!$P$3:$P$89))*(HQ!$P$3:$P$89))} -> 18 | H22: {=SUMPRODUCT((HQ!$T$3:$T$89>=H40)*(HQ!$T$3:$T$89<=H41)*(ISNUMBER(HQ!$P$3:$P$89))*(HQ!$P$3:$P$89))} -> 11 | I22: {=SUMPRODUCT((HQ!$T$3:$T$89>=I40)*(HQ!$T$3:$T$89<=I41)*(ISNUMBER(HQ!$P$3:$P$89))*(HQ!$P$3:$P$89))} -> 15 | ... O22: {=SUMPRODUCT((HQ!$T$3:$T$89>=O40)*(HQ!$T$3:$T$89<=O41)*(ISNUMBER(HQ!$P$3:$P$89))*(HQ!$P$3:$P$89))} -> 0 | P22: =SUM(B22:O22) -> 183
A23: มากกว่าแผน (เครื่อง) | B23: =MAX(B22-B21,0) -> 0 | C23: =MAX(C22-C21,0) -> 0 | D23: =MAX(D22-D21,0) -> 0 | E23: =MAX(E22-E21,0) -> 0 | F23: =MAX(F22-F21,0) -> 0 | G23: =MAX(G22-G21,0) -> 0 | H23: =MAX(H22-H21,0) -> 0 | I23: =MAX(I22-I21,0) -> 0 | ... P23: =MAX(P22-P21,0) -> 0
A24: ต่ำกว่าแผน (เครื่อง) | B24: =MAX(B21-B22,0) -> 7 | C24: =MAX(C21-C22,0) -> 0 | D24: =MAX(D21-D22,0) -> 0 | E24: =MAX(E21-E22,0) -> 0 | F24: =MAX(F21-F22,0) -> 0 | G24: =MAX(G21-G22,0) -> 0 | H24: =MAX(H21-H22,0) -> 0 | I24: =MAX(I21-I22,0) -> 0 | ... P24: =MAX(P21-P22,0) -> 10
A25: % ความก้าวหน้า Migration | B25: =IF(B21=0,IF(B22=0,"-","100%"),B22/B21) -> 0.79411765 | C25: =IF(C21=0,IF(C22=0,"-","100%"),C22/C21) -> 1 | D25: =IF(D21=0,IF(D22=0,"-","100%"),D22/D21) -> 1 | E25: =IF(E21=0,IF(E22=0,"-","100%"),E22/E21) -> 1 | F25: =IF(F21=0,IF(F22=0,"-","100%"),F22/F21) -> 1 | G25: =IF(G21=0,IF(G22=0,"-","100%"),G22/G21) -> 1 | H25: =IF(H21=0,IF(H22=0,"-","100%"),H22/H21) -> 1 | I25: =IF(I21=0,IF(I22=0,"-","100%"),I22/I21) -> 1 | ... O25: =IF(O21=0,IF(O22=0,"-","100%"),O22/O21) -> - | P25: =IF(P21=0,"-",P22/P21) -> 0.94818653
A27: ▌ สรุปภาพรวมและความก้าวหน้าสะสม
A28: % ความก้าวหน้าโดยรวม (รายสัปดาห์) | B28: =IF(B7=0,"-",(B12+B17+B22)/(B7*3)) -> 0.85294118 | C28: =IF(C7=0,"-",(C12+C17+C22)/(C7*3)) -> 1 | D28: =IF(D7=0,"-",(D12+D17+D22)/(D7*3)) -> 1 | E28: =IF(E7=0,"-",(E12+E17+E22)/(E7*3)) -> 1 | F28: =IF(F7=0,"-",(F12+F17+F22)/(F7*3)) -> 1 | G28: =IF(G7=0,"-",(G12+G17+G22)/(G7*3)) -> 1 | H28: =IF(H7=0,"-",(H12+H17+H22)/(H7*3)) -> 1 | I28: =IF(I7=0,"-",(I12+I17+I22)/(I7*3)) -> 1 | ... P28: =IF(P7=0,"-",(P12+P17+P22)/(P7*3)) -> 0.96545769
A30: จำนวนอุปกรณ์สะสมตามแผน (เครื่อง) | B30: =SUM($B7:B7) -> 34 | C30: =SUM($B7:C7) -> 44 | D30: =SUM($B7:D7) -> 53 | E30: =SUM($B7:E7) -> 105 | F30: =SUM($B7:F7) -> 119 | G30: =SUM($B7:G7) -> 137 | H30: =SUM($B7:H7) -> 148 | I30: =SUM($B7:I7) -> 163 | ... O30: =SUM($B7:O7) -> 193 | P30: =P7 -> 193
A31: จำนวนที่เสร็จสิ้นสะสม - ผลจริง (เครื่อง) | B31: =SUM($B22:B22) -> 27 | C31: =SUM($B22:C22) -> 37 | D31: =SUM($B22:D22) -> 46 | E31: =SUM($B22:E22) -> 98 | F31: =SUM($B22:F22) -> 112 | G31: =SUM($B22:G22) -> 130 | H31: =SUM($B22:H22) -> 141 | I31: =SUM($B22:I22) -> 156 | ... O31: =SUM($B22:O22) -> 183 | P31: =P22 -> 183
A32: % สะสมผลจริงเทียบเป้าหมายรวม | B32: =IF($P$7=0,"-",B31/$P$7) -> 0.13989637 | C32: =IF($P$7=0,"-",C31/$P$7) -> 0.19170984 | D32: =IF($P$7=0,"-",D31/$P$7) -> 0.23834197 | E32: =IF($P$7=0,"-",E31/$P$7) -> 0.50777202 | F32: =IF($P$7=0,"-",F31/$P$7) -> 0.58031088 | G32: =IF($P$7=0,"-",G31/$P$7) -> 0.67357513 | H32: =IF($P$7=0,"-",H31/$P$7) -> 0.73056995 | I32: =IF($P$7=0,"-",I31/$P$7) -> 0.80829016 | ... O32: =IF($P$7=0,"-",O31/$P$7) -> 0.94818653 | P32: =IF(P7=0,"-",P31/P7) -> 0.94818653
A33: % สะสมตามแผนเทียบเป้าหมายรวม | B33: =IF($P$7=0,"-",B30/$P$7) -> 0.1761658 | C33: =IF($P$7=0,"-",C30/$P$7) -> 0.22797927 | D33: =IF($P$7=0,"-",D30/$P$7) -> 0.2746114 | E33: =IF($P$7=0,"-",E30/$P$7) -> 0.54404145 | F33: =IF($P$7=0,"-",F30/$P$7) -> 0.61658031 | G33: =IF($P$7=0,"-",G30/$P$7) -> 0.70984456 | H33: =IF($P$7=0,"-",H30/$P$7) -> 0.76683938 | I33: =IF($P$7=0,"-",I30/$P$7) -> 0.84455959 | ... O33: =IF($P$7=0,"-",O30/$P$7) -> 1 | P33: =IF(P7=0,"-",P30/P7) -> 1
A35: หมายเหตุ: ทุกตัวเลขคำนวณอัตโนมัติจาก sheet HQ | col G = จำนวนอุปกรณ์ใหม่ | col P = วันที่เริ่ม (Helper) | col K/L/M = Config/Install/Migration ผลจริง
B40: =DATE(2026,2,2) -> 46055 | C40: =DATE(2026,2,9) -> 46062 | D40: =DATE(2026,2,16) -> 46069 | E40: =DATE(2026,2,23) -> 46076 | F40: =DATE(2026,3,2) -> 46083 | G40: =DATE(2026,3,9) -> 46090 | H40: =DATE(2026,3,16) -> 46097 | I40: =DATE(2026,3,23) -> 46104 | J40: =DATE(2026,3,30) -> 46111 | K40: =J40+7 -> 46118 | L40: =K40+7 -> 46125 | M40: =L40+7 -> 46132 | N40: =M40+7 -> 46139 | O40: =N40+7 -> 46146
B41: =DATE(2026,2,8) -> 46061 | C41: =DATE(2026,2,15) -> 46068 | D41: =DATE(2026,2,22) -> 46075 | E41: =DATE(2026,3,1) -> 46082 | F41: =DATE(2026,3,8) -> 46089 | G41: =DATE(2026,3,15) -> 46096 | H41: =DATE(2026,3,22) -> 46103 | I41: =DATE(2026,3,29) -> 46110 | J41: =DATE(2026,4,5) -> 46117 | K41: =J41+7 -> 46124 | L41: =K41+7 -> 46131 | M41: =L41+7 -> 46138 | N41: =M41+7 -> 46145 | O41: =N41+7 -> 46152

Sheet HQ-รายวัน
A1: สรุปแผนความก้าวหน้ารายวัน - สนญ. (HQ)
A2: ช่วงวันที่ 3 ก.พ. – 9 มี.ค. 69 | แสดงทุกวัน (วันที่ไม่มีแผน = 0) | สูตรดึงข้อมูลอัตโนมัติจาก sheet HQ
A4: รายการ | B4: =TEXT(B42, "d mmm") -> 3 ก.พ. | C4: =TEXT(C42, "d mmm") -> 4 ก.พ. | D4: =TEXT(D42, "d mmm") -> 5 ก.พ. | E4: =TEXT(E42, "d mmm") -> 6 ก.พ. | F4: =TEXT(F42, "d mmm") -> 7 ก.พ. | G4: =TEXT(G42, "d mmm") -> 8 ก.พ. | H4: =TEXT(H42, "d mmm") -> 9 ก.พ. | I4: =TEXT(I42, "d mmm") -> 10 ก.พ. | ... CT4: =TEXT(CT42, "d mmm") -> 10 พ.ค. | CU4: รวมทั้งหมด
B5: =TEXT(B42, "ddd") -> อ. | C5: =TEXT(C42, "ddd") -> พ. | D5: =TEXT(D42, "ddd") -> พฤ. | E5: =TEXT(E42, "ddd") -> ศ. | F5: =TEXT(F42, "ddd") -> ส. | G5: =TEXT(G42, "ddd") -> อา. | H5: =TEXT(H42, "ddd") -> จ. | I5: =TEXT(I42, "ddd") -> อ. | ... CT5: =TEXT(CT42, "ddd") -> อา.
A6: ▌ จำนวนอุปกรณ์ที่วางแผนติดตั้ง-Migration (เครื่อง)
A7: จำนวนอุปกรณ์ตามแผน (เครื่อง) | B7: {=SUMPRODUCT((HQ!$T$3:$T$89=B42)*(ISNUMBER(HQ!$G$3:$G$89))*(HQ!$G$3:$G$89))} -> 34 | C7: {=SUMPRODUCT((HQ!$T$3:$T$89=C42)*(ISNUMBER(HQ!$G$3:$G$89))*(HQ!$G$3:$G$89))} -> 0 | D7: {=SUMPRODUCT((HQ!$T$3:$T$89=D42)*(ISNUMBER(HQ!$G$3:$G$89))*(HQ!$G$3:$G$89))} -> 0 | E7: {=SUMPRODUCT((HQ!$T$3:$T$89=E42)*(ISNUMBER(HQ!$G$3:$G$89))*(HQ!$G$3:$G$89))} -> 0 | F7: {=SUMPRODUCT((HQ!$T$3:$T$89=F42)*(ISNUMBER(HQ!$G$3:$G$89))*(HQ!$G$3:$G$89))} -> 0 | G7: {=SUMPRODUCT((HQ!$T$3:$T$89=G42)*(ISNUMBER(HQ!$G$3:$G$89))*(HQ!$G$3:$G$89))} -> 0 | H7: {=SUMPRODUCT((HQ!$T$3:$T$89=H42)*(ISNUMBER(HQ!$G$3:$G$89))*(HQ!$G$3:$G$89))} -> 0 | I7: {=SUMPRODUCT((HQ!$T$3:$T$89=I42)*(ISNUMBER(HQ!$G$3:$G$89))*(HQ!$G$3:$G$89))} -> 0 | ... CT7: {=SUMPRODUCT((HQ!$T$3:$T$89=CT42)*(ISNUMBER(HQ!$G$3:$G$89))*(HQ!$G$3:$G$89))} -> 0 | CU7: {=SUMPRODUCT((ISNUMBER(HQ!$G$3:$G$89))*(HQ!$G$3:$G$89))} -> 193
A8: % แผนรายวัน (ของยอดรวม) | B8: =IF(B7=0,0,B7/$CU$7) -> 0.1761658 | C8: =IF(C7=0,0,C7/$CU$7) -> 0 | D8: =IF(D7=0,0,D7/$CU$7) -> 0 | E8: =IF(E7=0,0,E7/$CU$7) -> 0 | F8: =IF(F7=0,0,F7/$CU$7) -> 0 | G8: =IF(G7=0,0,G7/$CU$7) -> 0 | H8: =IF(H7=0,0,H7/$CU$7) -> 0 | I8: =IF(I7=0,0,I7/$CU$7) -> 0 | ... CT8: =IF(CT7=0,0,CT7/$CU$7) -> 0 | CU8: =CU7/CU7 -> 1
A10: ▌ Configuration
A11: แผน (เครื่อง) | B11: =B7 -> 34 | C11: =C7 -> 0 | D11: =D7 -> 0 | E11: =E7 -> 0 | F11: =F7 -> 0 | G11: =G7 -> 0 | H11: =H7 -> 0 | I11: =I7 -> 0 | ... CU11: =CU7 -> 193
A12: ผลจริง (เครื่อง) | B12: {=SUMPRODUCT((HQ!$T$3:$T$89=B42)*(ISNUMBER(HQ!$N$3:$N$89))*(HQ!$N$3:$N$89))} -> 30 | C12: {=SUMPRODUCT((HQ!$T$3:$T$89=C42)*(ISNUMBER(HQ!$N$3:$N$89))*(HQ!$N$3:$N$89))} -> 0 | D12: {=SUMPRODUCT((HQ!$T$3:$T$89=D42)*(ISNUMBER(HQ!$N$3:$N$89))*(HQ!$N$3:$N$89))} -> 0 | E12: {=SUMPRODUCT((HQ!$T$3:$T$89=E42)*(ISNUMBER(HQ!$N$3:$N$89))*(HQ!$N$3:$N$89))} -> 0 | F12: {=SUMPRODUCT((HQ!$T$3:$T$89=F42)*(ISNUMBER(HQ!$N$3:$N$89))*(HQ!$N$3:$N$89))} -> 0 | G12: {=SUMPRODUCT((HQ!$T$3:$T$89=G42)*(ISNUMBER(HQ!$N$3:$N$89))*(HQ!$N$3:$N$89))} -> 0 | H12: {=SUMPRODUCT((HQ!$T$3:$T$89=H42)*(ISNUMBER(HQ!$N$3:$N$89))*(HQ!$N$3:$N$89))} -> 0 | I12: {=SUMPRODUCT((HQ!$T$3:$T$89=I42)*(ISNUMBER(HQ!$N$3:$N$89))*(HQ!$N$3:$N$89))} -> 0 | ... CT12: {=SUMPRODUCT((HQ!$T$3:$T$89=CT42)*(ISNUMBER(HQ!$N$3:$N$89))*(HQ!$N$3:$N$89))} -> 0 | CU12: =SUM(B12:CT12) -> 188
A13: % ความก้าวหน้า Configuration | B13: =IF(B11=0,IF(B12=0,0,1),B12/B11) -> 0.88235294 | C13: =IF(C11=0,IF(C12=0,0,1),C12/C11) -> 0 | D13: =IF(D11=0,IF(D12=0,0,1),D12/D11) -> 0 | E13: =IF(E11=0,IF(E12=0,0,1),E12/E11) -> 0 | F13: =IF(F11=0,IF(F12=0,0,1),F12/F11) -> 0 | G13: =IF(G11=0,IF(G12=0,0,1),G12/G11) -> 0 | H13: =IF(H11=0,IF(H12=0,0,1),H12/H11) -> 0 | I13: =IF(I11=0,IF(I12=0,0,1),I12/I11) -> 0 | ... CT13: =IF(CT11=0,IF(CT12=0,0,1),CT12/CT11) -> 0 | CU13: =IF(CU11=0,"-",CU12/CU11) -> 0.97409326
A15: ▌ Installation
A16: แผน (เครื่อง) | B16: =B7 -> 34 | C16: =C7 -> 0 | D16: =D7 -> 0 | E16: =E7 -> 0 | F16: =F7 -> 0 | G16: =G7 -> 0 | H16: =H7 -> 0 | I16: =I7 -> 0 | ... CU16: =CU7 -> 193
A17: ผลจริง (เครื่อง) | B17: {=SUMPRODUCT((HQ!$T$3:$T$89=B42)*(ISNUMBER(HQ!$O$3:$O$89))*(HQ!$O$3:$O$89))} -> 30 | C17: {=SUMPRODUCT((HQ!$T$3:$T$89=C42)*(ISNUMBER(HQ!$O$3:$O$89))*(HQ!$O$3:$O$89))} -> 0 | D17: {=SUMPRODUCT((HQ!$T$3:$T$89=D42)*(ISNUMBER(HQ!$O$3:$O$89))*(HQ!$O$3:$O$89))} -> 0 | E17: {=SUMPRODUCT((HQ!$T$3:$T$89=E42)*(ISNUMBER(HQ!$O$3:$O$89))*(HQ!$O$3:$O$89))} -> 0 | F17: {=SUMPRODUCT((HQ!$T$3:$T$89=F42)*(ISNUMBER(HQ!$O$3:$O$89))*(HQ!$O$3:$O$89))} -> 0 | G17: {=SUMPRODUCT((HQ!$T$3:$T$89=G42)*(ISNUMBER(HQ!$O$3:$O$89))*(HQ!$O$3:$O$89))} -> 0 | H17: {=SUMPRODUCT((HQ!$T$3:$T$89=H42)*(ISNUMBER(HQ!$O$3:$O$89))*(HQ!$O$3:$O$89))} -> 0 | I17: {=SUMPRODUCT((HQ!$T$3:$T$89=I42)*(ISNUMBER(HQ!$O$3:$O$89))*(HQ!$O$3:$O$89))} -> 0 | ... CT17: {=SUMPRODUCT((HQ!$T$3:$T$89=CT42)*(ISNUMBER(HQ!$O$3:$O$89))*(HQ!$O$3:$O$89))} -> 0 | CU17: =SUM(B17:CT17) -> 188
A18: % ความก้าวหน้า Installation | B18: =IF(B16=0,IF(B17=0,0,1),B17/B16) -> 0.88235294 | C18: =IF(C16=0,IF(C17=0,0,1),C17/C16) -> 0 | D18: =IF(D16=0,IF(D17=0,0,1),D17/D16) -> 0 | E18: =IF(E16=0,IF(E17=0,0,1),E17/E16) -> 0 | F18: =IF(F16=0,IF(F17=0,0,1),F17/F16) -> 0 | G18: =IF(G16=0,IF(G17=0,0,1),G17/G16) -> 0 | H18: =IF(H16=0,IF(H17=0,0,1),H17/H16) -> 0 | I18: =IF(I16=0,IF(I17=0,0,1),I17/I16) -> 0 | ... CT18: =IF(CT16=0,IF(CT17=0,0,1),CT17/CT16) -> 0 | CU18: =IF(CU16=0,"-",CU17/CU16) -> 0.97409326
A20: ▌ Migration
A21: แผน (เครื่อง) | B21: =B7 -> 34 | C21: =C7 -> 0 | D21: =D7 -> 0 | E21: =E7 -> 0 | F21: =F7 -> 0 | G21: =G7 -> 0 | H21: =H7 -> 0 | I21: =I7 -> 0 | ... CU21: =CU7 -> 193
A22: ผลจริง (เครื่อง) | B22: {=SUMPRODUCT((HQ!$T$3:$T$89=B42)*(ISNUMBER(HQ!$P$3:$P$89))*(HQ!$P$3:$P$89))} -> 27 | C22: {=SUMPRODUCT((HQ!$T$3:$T$89=C42)*(ISNUMBER(HQ!$P$3:$P$89))*(HQ!$P$3:$P$89))} -> 0 | D22: {=SUMPRODUCT((HQ!$T$3:$T$89=D42)*(ISNUMBER(HQ!$P$3:$P$89))*(HQ!$P$3:$P$89))} -> 0 | E22: {=SUMPRODUCT((HQ!$T$3:$T$89=E42)*(ISNUMBER(HQ!$P$3:$P$89))*(HQ!$P$3:$P$89))} -> 0 | F22: {=SUMPRODUCT((HQ!$T$3:$T$89=F42)*(ISNUMBER(HQ!$P$3:$P$89))*(HQ!$P$3:$P$89))} -> 0 | G22: {=SUMPRODUCT((HQ!$T$3:$T$89=G42)*(ISNUMBER(HQ!$P$3:$P$89))*(HQ!$P$3:$P$89))} -> 0 | H22: {=SUMPRODUCT((HQ!$T$3:$T$89=H42)*(ISNUMBER(HQ!$P$3:$P$89))*(HQ!$P$3:$P$89))} -> 0 | I22: {=SUMPRODUCT((HQ!$T$3:$T$89=I42)*(ISNUMBER(HQ!$P$3:$P$89))*(HQ!$P$3:$P$89))} -> 0 | ... CT22: {=SUMPRODUCT((HQ!$T$3:$T$89=CT42)*(ISNUMBER(HQ!$P$3:$P$89))*(HQ!$P$3:$P$89))} -> 0 | CU22: =SUM(B22:CT22) -> 183
A23: มากกว่าแผน (เครื่อง) | B23: =MAX(B22-B21,0) -> 0 | C23: =MAX(C22-C21,0) -> 0 | D23: =MAX(D22-D21,0) -> 0 | E23: =MAX(E22-E21,0) -> 0 | F23: =MAX(F22-F21,0) -> 0 | G23: =MAX(G22-G21,0) -> 0 | H23: =MAX(H22-H21,0) -> 0 | I23: =MAX(I22-I21,0) -> 0 | ... CU23: =MAX(CU22-CU21,0) -> 0
A24: ต่ำกว่าแผน (เครื่อง) | B24: =MAX(B21-B22,0) -> 7 | C24: =MAX(C21-C22,0) -> 0 | D24: =MAX(D21-D22,0) -> 0 | E24: =MAX(E21-E22,0) -> 0 | F24: =MAX(F21-F22,0) -> 0 | G24: =MAX(G21-G22,0) -> 0 | H24: =MAX(H21-H22,0) -> 0 | I24: =MAX(I21-I22,0) -> 0 | ... CU24: =MAX(CU21-CU22,0) -> 10
A25: % ความก้าวหน้า Migration | B25: =IF(B21=0,IF(B22=0,0,1),B22/B21) -> 0.79411765 | C25: =IF(C21=0,IF(C22=0,0,1),C22/C21) -> 0 | D25: =IF(D21=0,IF(D22=0,0,1),D22/D21) -> 0 | E25: =IF(E21=0,IF(E22=0,0,1),E22/E21) -> 0 | F25: =IF(F21=0,IF(F22=0,0,1),F22/F21) -> 0 | G25: =IF(G21=0,IF(G22=0,0,1),G22/G21) -> 0 | H25: =IF(H21=0,IF(H22=0,0,1),H22/H21) -> 0 | I25: =IF(I21=0,IF(I22=0,0,1),I22/I21) -> 0 | ... CT25: =IF(CT21=0,IF(CT22=0,0,1),CT22/CT21) -> 0 | CU25: =IF(CU21=0,"-",CU22/CU21) -> 0.94818653
A27: ▌ สรุปภาพรวมและความก้าวหน้าสะสม
A28: % ความก้าวหน้าโดยรวมรายวัน | B28: =IF(B7=0,0,(B12+B17+B22)/(B7*3)) -> 0.85294118 | C28: =IF(C7=0,0,(C12+C17+C22)/(C7*3)) -> 0 | D28: =IF(D7=0,0,(D12+D17+D22)/(D7*3)) -> 0 | E28: =IF(E7=0,0,(E12+E17+E22)/(E7*3)) -> 0 | F28: =IF(F7=0,0,(F12+F17+F22)/(F7*3)) -> 0 | G28: =IF(G7=0,0,(G12+G17+G22)/(G7*3)) -> 0 | H28: =IF(H7=0,0,(H12+H17+H22)/(H7*3)) -> 0 | I28: =IF(I7=0,0,(I12+I17+I22)/(I7*3)) -> 0 | ... CT28: =IF(CT7=0,0,(CT12+CT17+CT22)/(CT7*3)) -> 0 | CU28: =IF(CU7=0,"-",(CU12+CU17+CU22)/(CU7*3)) -> 0.96545769
A30: จำนวนอุปกรณ์สะสมตามแผน (เครื่อง) | B30: =SUM($B7:B7) -> 34 | C30: =SUM($B7:C7) -> 34 | D30: =SUM($B7:D7) -> 34 | E30: =SUM($B7:E7) -> 34 | F30: =SUM($B7:F7) -> 34 | G30: =SUM($B7:G7) -> 34 | H30: =SUM($B7:H7) -> 34 | I30: =SUM($B7:I7) -> 34 | ... CT30: =SUM($B7:CT7) -> 193 | CU30: =CU7 -> 193
A31: จำนวนที่เสร็จสิ้นสะสม - ผลจริง (เครื่อง) | B31: =SUM($B22:B22) -> 27 | C31: =SUM($B22:C22) -> 27 | D31: =SUM($B22:D22) -> 27 | E31: =SUM($B22:E22) -> 27 | F31: =SUM($B22:F22) -> 27 | G31: =SUM($B22:G22) -> 27 | H31: =SUM($B22:H22) -> 27 | I31: =SUM($B22:I22) -> 27 | ... CT31: =SUM($B22:CT22) -> 183 | CU31: =CU22 -> 183
A32: % สะสมผลจริงเทียบเป้าหมายรวม | B32: =IF($CU$7=0,0,B31/$CU$7) -> 0.13989637 | C32: =IF($CU$7=0,0,C31/$CU$7) -> 0.13989637 | D32: =IF($CU$7=0,0,D31/$CU$7) -> 0.13989637 | E32: =IF($CU$7=0,0,E31/$CU$7) -> 0.13989637 | F32: =IF($CU$7=0,0,F31/$CU$7) -> 0.13989637 | G32: =IF($CU$7=0,0,G31/$CU$7) -> 0.13989637 | H32: =IF($CU$7=0,0,H31/$CU$7) -> 0.13989637 | I32: =IF($CU$7=0,0,I31/$CU$7) -> 0.13989637 | ... CT32: =IF($CU$7=0,0,CT31/$CU$7) -> 0.94818653 | CU32: =IF(CU7=0,"-",CU31/CU7) -> 0.94818653
A33: % สะสมตามแผนเทียบเป้าหมายรวม | B33: =IF($CU$7=0,0,B30/$CU$7) -> 0.1761658 | C33: =IF($CU$7=0,0,C30/$CU$7) -> 0.1761658 | D33: =IF($CU$7=0,0,D30/$CU$7) -> 0.1761658 | E33: =IF($CU$7=0,0,E30/$CU$7) -> 0.1761658 | F33: =IF($CU$7=0,0,F30/$CU$7) -> 0.1761658 | G33: =IF($CU$7=0,0,G30/$CU$7) -> 0.1761658 | H33: =IF($CU$7=0,0,H30/$CU$7) -> 0.1761658 | I33: =IF($CU$7=0,0,I30/$CU$7) -> 0.1761658 | ... CT33: =IF($CU$7=0,0,CT30/$CU$7) -> 1 | CU33: =IF(CU7=0,"-",CU30/CU7) -> 1
A35: หมายเหตุ: วันเสาร์-อาทิตย์ = header สีเทา | วันที่ไม่มีแผนงาน = 0 | สูตรดึงข้อมูลอัตโนมัติจาก HQ col G (จำนวน), col P (วันที่), col K/L/M (ผลจริง)
